Workbook

Sheet 측정일지_업로드(25하) 천안
AD1: 1 | AF1: 3 | AG1: 4 | AI1: 7 | AJ1: 8 | AK1: 9 | AL1: 10 | AM1: 11
A2: 코드* | B2: 측정년도* | C2: 측정주기* | D2: 비고 | E2: 지정한계_관할지청* | F2: 공문연번 | G2: 연번 | H2: 5인 이상 연번 | I2: 측정시작일 | J2: 측정종료일 | K2: 완료여부 | L2: 측정자 | M2: 소재지 관할청 | N2: 사업장명* | O2: 총인원 | P2: 사업자번호 | Q2: 산재보험번호 | R2: 대표자명 | S2: 국고지원여부 | T2: 주소 | U2: 전화번호 | V2: 팩스번호 | W2: 담당자명 | X2: 담당자직책 | Y2: 담당자휴대폰 | Z2: 담당자이메일 | AA2: K2B 전송일 | AB2: K2B 전송자 | AC2: 계산서 이메일 | AD2: 전자계산서 발행일 | AE2: 측정비(합계) | AF2: 측정비(사업장) | AG2: 측정비(국고) | AH2: 입금액(합계) | AI2: 입금일(사업장) | AJ2: 입금액(사업장) | AK2: 입금일(국고) | AL2: 입금액(국고) | AM2: 특이사항
A3: H0395 | B3: 2025 | C3: 하반기 | D3: 최초실시, 공정의 수시변경 | E3: 천안 | F3: ="천-"&'25하-천안140'!A3 -> 천-128 | G3: 1 | H3: 1 | I3: 45854 | J3: 45854 | L3: 고유빈 | M3: 천안 | N3: 태인건설산업 주식회사 MG인재개발원 승강기 설치공사 | O3: 10 | P3: 5148186597 | Q3: 51481865976 | R3: 손찬우 | T3: 충청남도 천안시 동남구 목천읍 삼방로 346 (동리, MG인재개발원) | W3: 박윤수 | X3: 소장 | Y3: 010-3528-0816 | Z3: soo19421@hanmail.net | AA3: 7월 28일 | AB3: 고유빈 | AC3: sonsukgun@nate.com | AD3: =VLOOKUP(A3,'계산서(25하-천안)'!$X$3:$AI$104,2,FALSE) -> 45869 | AF3: =VLOOKUP(A3,'계산서(25하-천안)'!$X$3:$AI$104,3,FALSE) -> 800000 | AG3: =VLOOKUP(A3,'계산서(25하-천안)'!$X$3:$AI$104,4,FALSE) -> 0 | AI3: =VLOOKUP(A3,'계산서(25하-천안)'!$X$3:$AI$104,2,FALSE) -> 45869 | AJ3: =VLOOKUP(A3,'계산서(25하-천안)'!$X$3:$AI$104,8,FALSE) -> 800000 | AK3: =VLOOKUP(A3,'계산서(25하-천안)'!$X$3:$AI$104,9,FALSE) -> 국고 X | AL3: =VLOOKUP(A3,'계산서(25하-천안)'!$X$3:$AI$104,10,FALSE) -> 0 | AM3: =VLOOKUP(A3,'계산서(25하-천안)'!$X$3:$AI$104,12,FALSE) -> 0
A4: H0394 | B4: 2025 | C4: 하반기 | D4: 타기관 신규 | E4: 천안 | F4: ="천-"&'25하-천안140'!A4 -> 천-129 | G4: 2 | H4: 2 | I4: 45855 | J4: 45855 | L4: 강종구 | M4: 경기 | N4: 케이케이엘 유한회사 | O4: 30 | P4: 1358638733 | Q4: 13586387330 | R4: 정주익, MICHAEL KEITH HIETBRINK | T4: 경기도 화성시 장안면 장안공단2길 66-9 (수촌리) | U4: 031-8055-2912 | V4: 031-8055-2990 | W4: 김진석 | X4: 매니저 | Y4: 010-8844-2349 | Z4: jinseok.kim1@kkl-kr.com | AA4: 45874 | AB4: 강종구 | AC4: jinseok.kim1@kkl-kr.com | AD4: =VLOOKUP(A4,'계산서(25하-천안)'!$X$3:$AI$104,2,FALSE) -> 45880 | AF4: =VLOOKUP(A4,'계산서(25하-천안)'!$X$3:$AI$104,3,FALSE) -> 1000000 | AG4: =VLOOKUP(A4,'계산서(25하-천안)'!$X$3:$AI$104,4,FALSE) -> 400000 | AI4: =VLOOKUP(A4,'계산서(25하-천안)'!$X$3:$AI$104,2,FALSE) -> 45880 | AJ4: =VLOOKUP(A4,'계산서(25하-천안)'!$X$3:$AI$104,8,FALSE) -> 1000000 | AK4: =VLOOKUP(A4,'계산서(25하-천안)'!$X$3:$AI$104,9,FALSE) -> 45890 | AL4: =VLOOKUP(A4,'계산서(25하-천안)'!$X$3:$AI$104,10,FALSE) -> 400000 | AM4: =VLOOKUP(A4,'계산서(25하-천안)'!$X$3:$AI$104,12,FALSE) -> 0
A5: H0200 | B5: 2025 | C5: 하반기 | E5: 천안 | F5: ="천-"&'25하-천안140'!A5 -> 천-130 | G5: 3 | H5: 3 | I5: 45856 | J5: 45856 | L5: 강종구 | M5: 천안 | N5: 인주농협 미곡처리장 | O5: 7 | P5: 8158200034 | Q5: 81582000340 | R5: 김진권 | T5: 충청남도 아산시 인주면 걸매길 6-17 (걸매리, 인주농협조곡처리장) | U5: 041-533-3289 | V5: 041-533-3290 | W5: 강은주 | X5: 과장대리 | Y5: 010-5429-1637 | Z5: nh483089@nonghyup.com | AA5: 45862 | AB5: 강종구 | AC5: nh483089@nonghyup.com | AD5: =VLOOKUP(A5,'계산서(25하-천안)'!$X$3:$AI$104,2,FALSE) -> 45862 | AF5: =VLOOKUP(A5,'계산서(25하-천안)'!$X$3:$AI$104,3,FALSE) -> 700000 | AG5: =VLOOKUP(A5,'계산서(25하-천안)'!$X$3:$AI$104,4,FALSE) -> 0 | AI5: =VLOOKUP(A5,'계산서(25하-천안)'!$X$3:$AI$104,2,FALSE) -> 45862 | AJ5: =VLOOKUP(A5,'계산서(25하-천안)'!$X$3:$AI$104,8,FALSE) -> 700000 | AK5: =VLOOKUP(A5,'계산서(25하-천안)'!$X$3:$AI$104,9,FALSE) -> 국고 X | AL5: =VLOOKUP(A5,'계산서(25하-천안)'!$X$3:$AI$104,10,FALSE) -> 0 | AM5: =VLOOKUP(A5,'계산서(25하-천안)'!$X$3:$AI$104,12,FALSE) -> 0
A6: H0139 | B6: 2025 | C6: 하반기 | E6: 천안 | F6: ="천-"&'25하-천안140'!A6 -> 천-131 | G6: 4 | H6: 3 | I6: 45867 | J6: 45867 | L6: 고유빈 | M6: 천안 | N6: 현테크 | O6: 2 | P6: 3122393828 | Q6: 91610280151 | R6: 유지만 | T6: 충청남도 천안시 서북구 직산읍 신갈1길 53-15 (신갈리) | U6: 041-583-1871 | V6: 041-583-1872 | W6: 유지만 | X6: 대표 | Y6: 010-6422-6702 | Z6: youjm33@naver.com | AA6: 8월 21일 | AB6: 고유빈 | AC6: youjm33@naver.com | AD6: =VLOOKUP(A6,'계산서(25하-천안)'!$X$3:$AI$104,2,FALSE) -> 국고 전액 | AF6: =VLOOKUP(A6,'계산서(25하-천안)'!$X$3:$AI$104,3,FALSE) -> 0 | AG6: =VLOOKUP(A6,'계산서(25하-천안)'!$X$3:$AI$104,4,FALSE) -> 400000 | AI6: =VLOOKUP(A6,'계산서(25하-천안)'!$X$3:$AI$104,2,FALSE) -> 국고 전액 | AJ6: =VLOOKUP(A6,'계산서(25하-천안)'!$X$3:$AI$104,8,FALSE) -> 0 | AK6: =VLOOKUP(A6,'계산서(25하-천안)'!$X$3:$AI$104,9,FALSE) -> 45912 | AL6: =VLOOKUP(A6,'계산서(25하-천안)'!$X$3:$AI$104,10,FALSE) -> 400000 | AM6: =VLOOKUP(A6,'계산서(25하-천안)'!$X$3:$AI$104,12,FALSE) -> 0
A7: H0350 | B7: 2025 | C7: 하반기 | E7: 천안 | F7: ="천-"&'25하-천안140'!A7 -> 천-132 | G7: 5 | H7: 4 | I7: 45867 | J7: 45867 | L7: 강종구 | M7: 천안 | N7: 정연코퍼레이션 주식회사 | O7: 17 | P7: 3128664352 | Q7: 31286643520 | R7: 장두희 | T7: 충청남도 천안시 서북구 성환읍 왕지1길 156-7 (송덕리) | U7: 041-522-7072 | V7: 041-522-7074 | W7: 신지원 | Y7: 010-6483-0072 | Z7: sdmccv@naver.com | AA7: 45877 | AB7: 강종구 | AC7: wjhnc64352@hometax.go.kr | AD7: =VLOOKUP(A7,'계산서(25하-천안)'!$X$3:$AI$104,2,FALSE) -> 45877 | AF7: =VLOOKUP(A7,'계산서(25하-천안)'!$X$3:$AI$104,3,FALSE) -> 550000 | AG7: =VLOOKUP(A7,'계산서(25하-천안)'!$X$3:$AI$104,4,FALSE) -> 0 | AI7: =VLOOKUP(A7,'계산서(25하-천안)'!$X$3:$AI$104,2,FALSE) -> 45877 | AJ7: =VLOOKUP(A7,'계산서(25하-천안)'!$X$3:$AI$104,8,FALSE) -> 550000 | AK7: =VLOOKUP(A7,'계산서(25하-천안)'!$X$3:$AI$104,9,FALSE) -> 국고 X | AL7: =VLOOKUP(A7,'계산서(25하-천안)'!$X$3:$AI$104,10,FALSE) -> 0 | AM7: =VLOOKUP(A7,'계산서(25하-천안)'!$X$3:$AI$104,12,FALSE) -> 0
A8: H0117 | B8: 2025 | C8: 하반기 | E8: 천안 | F8: ="천-"&'25하-천안140'!A8 -> 천-133 | G8: 6 | H8: 4 | I8: 45868 | J8: 45868 | L8: 고유빈 | M8: 천안 | N8: 어썸치과기공소 | O8: 2 | P8: 5869300879 | Q8: 58693008790 | R8: 김성진 | T8: 충청남도 천안시 서북구 검은들3길 42, 602호 (불당동, C&J타워빌딩) | U8: 041-575-2857 | V8: 041-562-2806 | W8: 김성진 | X8: 소장(대표) | Y8: 010-9030-0252 | Z8: why0205@hanmail.net | AA8: 8월 21일 | AB8: 고유빈 | AC8: why0205@hanmail.net | AD8: =VLOOKUP(A8,'계산서(25하-천안)'!$X$3:$AI$104,2,FALSE) -> 국고 전액 | AF8: =VLOOKUP(A8,'계산서(25하-천안)'!$X$3:$AI$104,3,FALSE) -> 0 | AG8: =VLOOKUP(A8,'계산서(25하-천안)'!$X$3:$AI$104,4,FALSE) -> 400000 | AI8: =VLOOKUP(A8,'계산서(25하-천안)'!$X$3:$AI$104,2,FALSE) -> 국고 전액 | AJ8: =VLOOKUP(A8,'계산서(25하-천안)'!$X$3:$AI$104,8,FALSE) -> 0 | AK8: =VLOOKUP(A8,'계산서(25하-천안)'!$X$3:$AI$104,9,FALSE) -> 45912 | AL8: =VLOOKUP(A8,'계산서(25하-천안)'!$X$3:$AI$104,10,FALSE) -> 400000 | AM8: =VLOOKUP(A8,'계산서(25하-천안)'!$X$3:$AI$104,12,FALSE) -> 0
A9: H0396 | B9: 2025 | C9: 하반기 | D9: 타기관 신규 | E9: 천안 | F9: ="천-"&'25하-천안140'!A9 -> 천-134 | G9: 7 | H9: 5 | I9: 45869 | J9: 45869 | L9: 이주형 | M9: 성남 | N9: 일신산업전기 (주) | O9: 48 | P9: 1268157430 | Q9: 12681574300 | R9: 고수영 | T9: 경기도 광주시 광주대로 200-1(송정동) | U9: 031-797-1631 | V9: 031-797-2178 | W9: 신민재 | X9: 이사 | Y9: 010-2361-2820 | Z9: mjs7795@hanmail.net | AA9: 45889 | AB9: 이주형 | AC9: 99isieco@daum.net | AD9: =VLOOKUP(A9,'계산서(25하-천안)'!$X$3:$AI$104,2,FALSE) -> 45894 | AF9: =VLOOKUP(A9,'계산서(25하-천안)'!$X$3:$AI$104,3,FALSE) -> 400000 | AG9: =VLOOKUP(A9,'계산서(25하-천안)'!$X$3:$AI$104,4,FALSE) -> 400000 | AI9: =VLOOKUP(A9,'계산서(25하-천안)'!$X$3:$AI$104,2,FALSE) -> 45894 | AJ9: =VLOOKUP(A9,'계산서(25하-천안)'!$X$3:$AI$104,8,FALSE) -> 400000 | AK9: =VLOOKUP(A9,'계산서(25하-천안)'!$X$3:$AI$104,9,FALSE) -> 45923 | AL9: =VLOOKUP(A9,'계산서(25하-천안)'!$X$3:$AI$104,10,FALSE) -> 400000 | AM9: =VLOOKUP(A9,'계산서(25하-천안)'!$X$3:$AI$104,12,FALSE) -> 0
A10: H0398 | B10: 2025 | C10: 하반기 | D10: 최초실시, 공정의 수시변경 | E10: 천안 | F10: ="천-"&'25하-천안140'!A10 -> 천-135 | G10: 8 | H10: 6 | I10: 45869 | J10: 45869 | L10: 배윤민 | M10: 천안 | N10: 에이치디씨현대산업개발 주식회사 당진천안선 터널소방시설공사 | O10: 7 | P10: 3348600815 | Q10: 11481588536 | R10: 정경구, 조태제 | T10: 충청남도 아산시 영인면 토정로 148(역리) | U10: 041-543-6998 | V10: 041-543-6997 | W10: 손인기 | X10: 안전관리자 | Y10: 010-2089-5262 | Z10: 2807020@hdc-dvp.com | AA10: 45890 | AB10: 배윤민 | AC10: R1053ctdi@hdc-dvp.com | AD10: =VLOOKUP(A10,'계산서(25하-천안)'!$X$3:$AI$104,2,FALSE) -> 45894 | AF10: =VLOOKUP(A10,'계산서(25하-천안)'!$X$3:$AI$104,3,FALSE) -> 700000 | AG10: =VLOOKUP(A10,'계산서(25하-천안)'!$X$3:$AI$104,4,FALSE) -> 0 | AI10: =VLOOKUP(A10,'계산서(25하-천안)'!$X$3:$AI$104,2,FALSE) -> 45894 | AJ10: =VLOOKUP(A10,'계산서(25하-천안)'!$X$3:$AI$104,8,FALSE) -> 700000 | AK10: =VLOOKUP(A10,'계산서(25하-천안)'!$X$3:$AI$104,9,FALSE) -> 국고 X | AL10: =VLOOKUP(A10,'계산서(25하-천안)'!$X$3:$AI$104,10,FALSE) -> 0 | AM10: =VLOOKUP(A10,'계산서(25하-천안)'!$X$3:$AI$104,12,FALSE) -> 0
A11: H0149 | B11: 2025 | C11: 하반기 | D11: 고시물질, 소음85이상 | E11: 천안 | F11: ="천-"&'25하-천안140'!A11 -> 천-136 | G11: 9 | H11: 7 | I11: 45888 | J11: 45888 | L11: 강종구 | M11: 천안 | N11: 아산피앤피(주) | O11: 29 | P11: 3128137637 | Q11: 31281376370 | R11: 이병길, 이건우 | T11: 충청남도 아산시 선장면 학성로122번길 94 (죽산리) | U11: 041-541-5711 | V11: 041-541-5715 | W11: 이선미 | X11: 과장 | Y11: 010-4045-9979 | Z11: beauty@aspulp.co.kr | AA11: 45912 | AB11: 강종구 | AC11: beauty@aspulp.co.kr | AD11: =VLOOKUP(A11,'계산서(25하-천안)'!$X$3:$AI$104,2,FALSE) -> 45894 | AF11: =VLOOKUP(A11,'계산서(25하-천안)'!$X$3:$AI$104,3,FALSE) -> 500000 | AG11: =VLOOKUP(A11,'계산서(25하-천안)'!$X$3:$AI$104,4,FALSE) -> 400000 | AI11: =VLOOKUP(A11,'계산서(25하-천안)'!$X$3:$AI$104,2,FALSE) -> 45894 | AJ11: =VLOOKUP(A11,'계산서(25하-천안)'!$X$3:$AI$104,8,FALSE) -> 500000 | AK11: =VLOOKUP(A11,'계산서(25하-천안)'!$X$3:$AI$104,9,FALSE) -> 45944 | AL11: =VLOOKUP(A11,'계산서(25하-천안)'!$X$3:$AI$104,10,FALSE) -> 400000 | AM11: =VLOOKUP(A11,'계산서(25하-천안)'!$X$3:$AI$104,12,FALSE) -> 0
A12: H0123 | B12: 2025 | C12: 하반기 | D12: 고시물질 | E12: 천안 | F12: ="천-"&'25하-천안140'!A12 -> 천-137 | G12: 10 | H12: 7 | I12: 45890 | J12: 45890 | L12: 강종구 | M12: 천안 | N12: 한솔지에스 | O12: 4 | P12: 2661900602 | Q12: 26619006020 | R12: 김효식 | T12: 충청남도 천안시 서북구 직산읍 상덕2길 2 (자은가리) | U12: 041-553-1026 | V12: 041-552-1026 | W12: 김효식 | X12: 대표 | Y12: 010-5406-9859 | Z12: cacao003@hansolgs.com | AA12: 45919 | AB12: 강종구 | AC12: cacaco003@hansolgs.com | AD12: =VLOOKUP(A12,'계산서(25하-천안)'!$X$3:$AI$104,2,FALSE) -> 45894 | AF12: =VLOOKUP(A12,'계산서(25하-천안)'!$X$3:$AI$104,3,FALSE) -> 250000 | AG12: =VLOOKUP(A12,'계산서(25하-천안)'!$X$3:$AI$104,4,FALSE) -> 400000 | AI12: =VLOOKUP(A12,'계산서(25하-천안)'!$X$3:$AI$104,2,FALSE) -> 45894 | AJ12: =VLOOKUP(A12,'계산서(25하-천안)'!$X$3:$AI$104,8,FALSE) -> 250000 | AK12: =VLOOKUP(A12,'계산서(25하-천안)'!$X$3:$AI$104,9,FALSE) -> 45944 | AL12: =VLOOKUP(A12,'계산서(25하-천안)'!$X$3:$AI$104,10,FALSE) -> 400000 | AM12: =VLOOKUP(A12,'계산서(25하-천안)'!$X$3:$AI$104,12,FALSE) -> 0
A13: H0239 | B13: 2025 | C13: 하반기 | D13: 공정의 수시변경 | E13: 천안 | F13: ="천-"&'25하-천안140'!A13 -> 천-138 | G13: 11 | H13: 8 | I13: 45891 | J13: 45891 | L13: 강종구 | M13: 천안 | N13: 아산모터스 | O13: 11 | P13: 6912101853 | Q13: 69121018530 | R13: 심한주 | T13: 충청남도 아산시 곡교천로 159 (온천동) | U13: 041-546-0005 | V13: 041-546-0999 | W13: 심한주 | X13: 대표 | Y13: 010-8978-9809 | Z13: asan_motors@naver.com | AA13: 45919 | AB13: 강종구 | AC13: asan_motors@naver.com | AD13: =VLOOKUP(A13,'계산서(25하-천안)'!$X$3:$AI$104,2,FALSE) -> 45894 | AF13: =VLOOKUP(A13,'계산서(25하-천안)'!$X$3:$AI$104,3,FALSE) -> 350000 | AG13: =VLOOKUP(A13,'계산서(25하-천안)'!$X$3:$AI$104,4,FALSE) -> 400000 | AI13: =VLOOKUP(A13,'계산서(25하-천안)'!$X$3:$AI$104,2,FALSE) -> 45894 | AJ13: =VLOOKUP(A13,'계산서(25하-천안)'!$X$3:$AI$104,8,FALSE) -> 350000 | AK13: =VLOOKUP(A13,'계산서(25하-천안)'!$X$3:$AI$104,9,FALSE) -> 45944 | AL13: =VLOOKUP(A13,'계산서(25하-천안)'!$X$3:$AI$104,10,FALSE) -> 400000 | AM13: =VLOOKUP(A13,'계산서(25하-천안)'!$X$3:$AI$104,12,FALSE) -> 0
A14: H0240 | B14: 2025 | C14: 하반기 | D14: 공정의 수시변경 | E14: 천안 | F14: ="천-"&'25하-천안140'!A14 -> 천-139 | G14: 12 | H14: 9 | I14: 45891 | J14: 45891 | L14: 이태환 | M14: 천안 | N14: 아산현대서비스 주식회사 | O14: 27 | P14: 4488600924 | Q14: 44886009240 | R14: 맹의석 | T14: 충청남도 아산시 온천대로 1790-9 (남동) | U14: 041-531-1122 | V14: 041-534-0022 | W14: 황중현 | X14: 실장 | Y14: 010-7396-2674 | Z14: asanhd@nate.com | AA14: 45919 | AB14: 강종구 | AC14: asanhd@nate.com | AD14: =VLOOKUP(A14,'계산서(25하-천안)'!$X$3:$AI$104,2,FALSE) -> 45894 | AF14: =VLOOKUP(A14,'계산서(25하-천안)'!$X$3:$AI$104,3,FALSE) -> 450000 | AG14: =VLOOKUP(A14,'계산서(25하-천안)'!$X$3:$AI$104,4,FALSE) -> 400000 | AI14: =VLOOKUP(A14,'계산서(25하-천안)'!$X$3:$AI$104,2,FALSE) -> 45894 | AJ14: =VLOOKUP(A14,'계산서(25하-천안)'!$X$3:$AI$104,8,FALSE) -> 450000 | AK14: =VLOOKUP(A14,'계산서(25하-천안)'!$X$3:$AI$104,9,FALSE) -> 45944 | AL14: =VLOOKUP(A14,'계산서(25하-천안)'!$X$3:$AI$104,10,FALSE) -> 400000 | AM14: =VLOOKUP(A14,'계산서(25하-천안)'!$X$3:$AI$104,12,FALSE) -> 0
A15: H0270 | B15: 2025 | C15: 하반기 | D15: 공정의 수시변경 | E15: 천안 | F15: ="천-"&'25하-천안140'!A15 -> 천-140 | G15: 13 | H15: 10 | I15: 45891 | J15: 45891 | L15: 고유빈 | M15: 천안 | N15: 케이지모빌리티아산서비스센터 주식회사 | O15: 14 | P15: 1798700118 | Q15: 17987001180 | R15: 최재학 | T15: 충청남도 아산시 신리길 6 (신동) | U15: 041-549-5582 | V15: 041-549-5505 | W15: 정명용 | X15: 과장 | Y15: 010-5433-5278 | Z15: ksh5038@hanmail.net | AA15: 45919 | AB15: 강종구 | AC15: ksh5038@hanmail.net | AD15: =VLOOKUP(A15,'계산서(25하-천안)'!$X$3:$AI$104,2,FALSE) -> 45894 | AF15: =VLOOKUP(A15,'계산서(25하-천안)'!$X$3:$AI$104,3,FALSE) -> 350000 | AG15: =VLOOKUP(A15,'계산서(25하-천안)'!$X$3:$AI$104,4,FALSE) -> 400000 | AI15: =VLOOKUP(A15,'계산서(25하-천안)'!$X$3:$AI$104,2,FALSE) -> 45894 | AJ15: =VLOOKUP(A15,'계산서(25하-천안)'!$X$3:$AI$104,8,FALSE) -> 350000 | AK15: =VLOOKUP(A15,'계산서(25하-천안)'!$X$3:$AI$104,9,FALSE) -> 45944 | AL15: =VLOOKUP(A15,'계산서(25하-천안)'!$X$3:$AI$104,10,FALSE) -> 400000 | AM15: =VLOOKUP(A15,'계산서(25하-천안)'!$X$3:$AI$104,12,FALSE) -> 0
A16: H0401 | B16: 2025 | C16: 하반기 | D16: 고시물질, 소음85이상 | E16: 천안 | F16: ="천-"&'25하-천안140'!A16 -> 천-141 | G16: 14 | H16: 11 | I16: 45895 | J16: 45895 | L16: 이주형 | M16: 안산 | N16: (주) 두산금속 | O16: 23 | P16: 1408113291 | Q16: 14081132910 | R16: 김영이 | T16: 경기도 시흥시 마유로82번길 52 (정왕동) | U16: 031-432-0783 | V16: 031-432-0785 | W16: 김원경 | X16: 과장 | Y16: 010-9642-0201 | Z16: doosansm@hanmail.net | AA16: 45924 | AB16: 이주형 | AC16: doosansm@hanmail.net | AD16: =VLOOKUP(A16,'계산서(25하-천안)'!$X$3:$AI$104,2,FALSE) -> 45929 | AF16: =VLOOKUP(A16,'계산서(25하-천안)'!$X$3:$AI$104,3,FALSE) -> 300000 | AG16: =VLOOKUP(A16,'계산서(25하-천안)'!$X$3:$AI$104,4,FALSE) -> 400000 | AI16: =VLOOKUP(A16,'계산서(25하-천안)'!$X$3:$AI$104,2,FALSE) -> 45929 | AJ16: =VLOOKUP(A16,'계산서(25하-천안)'!$X$3:$AI$104,8,FALSE) -> 300000 | AK16: =VLOOKUP(A16,'계산서(25하-천안)'!$X$3:$AI$104,9,FALSE) -> 45952 | AL16: =VLOOKUP(A16,'계산서(25하-천안)'!$X$3:$AI$104,10,FALSE) -> 400000 | AM16: =VLOOKUP(A16,'계산서(25하-천안)'!$X$3:$AI$104,12,FALSE) -> 0
A17: H0400 | B17: 2025 | C17: 하반기 | D17: 고시물질 | E17: 천안 | F17: ="천-"&'25하-천안140'!A17 -> 천-142 | G17: 15 | H17: 12 | I17: 45895 | J17: 45895 | L17: 한기문 | M17: 안산 | N17: 두산판금 | O17: 16 | P17: 1340746934 | Q17: 13407469340 | R17: 주명구 | T17: 경기도 시흥시 공단3대로 153 (정왕동) | U17: 031-432-0783 | V17: 031-432-0785 | W17: 김원경 | X17: 과장 | Y17: 010-9642-0201 | Z17: doosansm@hanmail.net | AA17: 45924 | AB17: 이주형 | AC17: doosansm@hanmail.net | AD17: =VLOOKUP(A17,'계산서(25하-천안)'!$X$3:$AI$104,2,FALSE) -> 45929 | AF17: =VLOOKUP(A17,'계산서(25하-천안)'!$X$3:$AI$104,3,FALSE) -> 300000 | AG17: =VLOOKUP(A17,'계산서(25하-천안)'!$X$3:$AI$104,4,FALSE) -> 400000 | AI17: =VLOOKUP(A17,'계산서(25하-천안)'!$X$3:$AI$104,2,FALSE) -> 45929 | AJ17: =VLOOKUP(A17,'계산서(25하-천안)'!$X$3:$AI$104,8,FALSE) -> 300000 | AK17: =VLOOKUP(A17,'계산서(25하-천안)'!$X$3:$AI$104,9,FALSE) -> 45952 | AL17: =VLOOKUP(A17,'계산서(25하-천안)'!$X$3:$AI$104,10,FALSE) -> 400000 | AM17: =VLOOKUP(A17,'계산서(25하-천안)'!$X$3:$AI$104,12,FALSE) -> 0
A18: H0143 | B18: 2025 | C18: 하반기 | E18: 천안 | F18: ="천-"&'25하-천안140'!A18 -> 천-143 | G18: 16 | H18: 12 | I18: 45895 | J18: 45895 | L18: 고유빈 | M18: 천안 | N18: (주)쓰리디치과기공소 | O18: 3 | P18: 8348702116 | Q18: 83487021160 | R18: 원태희 | T18: 충청남도 천안시 서북구 불당21로 71, 7층 705호 (불당동) | U18: 041-555-2879 | V18: 041-555-2878 | W18: 김다겸 | X18: 주임 | Y18: 010-5870-2958 | Z18: office@theboston.co.kr | AA18: 9월 24일 | AB18: 배윤민 | AC18: 3ddentallab1@naver.com | AD18: =VLOOKUP(A18,'계산서(25하-천안)'!$X$3:$AI$104,2,FALSE) -> 45926 | AF18: =VLOOKUP(A18,'계산서(25하-천안)'!$X$3:$AI$104,3,FALSE) -> 600000 | AG18: =VLOOKUP(A18,'계산서(25하-천안)'!$X$3:$AI$104,4,FALSE) -> 400000 | AI18: =VLOOKUP(A18,'계산서(25하-천안)'!$X$3:$AI$104,2,FALSE) -> 45926 | AJ18: =VLOOKUP(A18,'계산서(25하-천안)'!$X$3:$AI$104,8,FALSE) -> 600000 | AK18: =VLOOKUP(A18,'계산서(25하-천안)'!$X$3:$AI$104,9,FALSE) -> 45944 | AL18: =VLOOKUP(A18,'계산서(25하-천안)'!$X$3:$AI$104,10,FALSE) -> 400000 | AM18: =VLOOKUP(A18,'계산서(25하-천안)'!$X$3:$AI$104,12,FALSE) -> 0
A19: H0142 | B19: 2025 | C19: 하반기 | D19: 고시물질 | E19: 천안 | F19: ="천-"&'25하-천안140'!A19 -> 천-144 | G19: 17 | H19: 13 | I19: 45895 | J19: 45895 | L19: 배윤민 | M19: 천안 | N19: 더보스톤치과병원 | O19: 57 | P19: 7941400586 | Q19: 79414005860 | R19: 원태희 | T19: 충청남도 천안시 서북구 불당33길 26 (불당동) | U19: 041-555-2879 | V19: 041-558-4001 | W19: 김다겸 | X19: 주임 | Y19: 010-5870-2958 | Z19: office@theboston.co.kr | AA19: 9월 24일 | AB19: 배윤민 | AC19: tax@theboston.co.kr | AD19: =VLOOKUP(A19,'계산서(25하-천안)'!$X$3:$AI$104,2,FALSE) -> 45926 | AF19: =VLOOKUP(A19,'계산서(25하-천안)'!$X$3:$AI$104,3,FALSE) -> 500000 | AG19: =VLOOKUP(A19,'계산서(25하-천안)'!$X$3:$AI$104,4,FALSE) -> 0 | AI19: =VLOOKUP(A19,'계산서(25하-천안)'!$X$3:$AI$104,2,FALSE) -> 45926 | AJ19: =VLOOKUP(A19,'계산서(25하-천안)'!$X$3:$AI$104,8,FALSE) -> 500000 | AK19: =VLOOKUP(A19,'계산서(25하-천안)'!$X$3:$AI$104,9,FALSE) -> 국고 X | AL19: =VLOOKUP(A19,'계산서(25하-천안)'!$X$3:$AI$104,10,FALSE) -> 0 | AM19: =VLOOKUP(A19,'계산서(25하-천안)'!$X$3:$AI$104,12,FALSE) -> 0
A20: H0296 | B20: 2025 | C20: 하반기 | D20: 고시물질 | E20: 천안 | F20: ="천-"&'25하-천안140'!A20 -> 천-145 | G20: 18 | H20: 14 | I20: 45895 | J20: 45895 | L20: 강종구 | M20: 천안 | N20: 주식회사 유기농기계 | O20: 8 | P20: 2918100624 | Q20: 29181006240 | R20: 김상호 | T20: 충청남도 천안시 서북구 직산읍 군수1길 112-16 (군서리) | U20: 041-567-2859 | V20: 041-568-2859 | W20: 김상범 | X20: 부장 | Y20: 010-9911-2859 | Z20: sadang3378@naver.com | AA20: 45919 | AB20: 강종구 | AC20: sadang3378@naver.com | AD20: =VLOOKUP(A20,'계산서(25하-천안)'!$X$3:$AI$104,2,FALSE) -> 45945 | AF20: =VLOOKUP(A20,'계산서(25하-천안)'!$X$3:$AI$104,3,FALSE) -> 650000 | AG20: =VLOOKUP(A20,'계산서(25하-천안)'!$X$3:$AI$104,4,FALSE) -> 400000 | AI20: =VLOOKUP(A20,'계산서(25하-천안)'!$X$3:$AI$104,2,FALSE) -> 45945 | AJ20: =VLOOKUP(A20,'계산서(25하-천안)'!$X$3:$AI$104,8,FALSE) -> 650000 | AK20: =VLOOKUP(A20,'계산서(25하-천안)'!$X$3:$AI$104,9,FALSE) -> 45944 | AL20: =VLOOKUP(A20,'계산서(25하-천안)'!$X$3:$AI$104,10,FALSE) -> 400000 | AM20: =VLOOKUP(A20,'계산서(25하-천안)'!$X$3:$AI$104,12,FALSE) -> 0
A21: H0250 | B21: 2025 | C21: 하반기 | E21: 천안 | F21: ="천-"&'25하-천안140'!A21 -> 천-146 | G21: 19 | H21: 14 | I21: 45909 | J21: 45909 | L21: 이주형 | M21: 천안 | N21: 건승티앤비 | O21: 3 | P21: 3123271675 | Q21: 31232716750 | R21: 김건남 | T21: 충청남도 천안시 동남구 성남면 성남로 230-21 (용원리) | U21: 041-555-7260 | V21: 041-556-7261 | W21: 김건남 | X21: 대표 | Y21: 010-9925-7260 | Z21: sonata8715@hanmail.net | AA21: 45931 | AB21: 이주형 | AC21: sonata8715@hanmail.net | AD21: =VLOOKUP(A21,'계산서(25하-천안)'!$X$3:$AI$104,2,FALSE) -> 국고 전액 | AF21: =VLOOKUP(A21,'계산서(25하-천안)'!$X$3:$AI$104,3,FALSE) -> 0 | AG21: =VLOOKUP(A21,'계산서(25하-천안)'!$X$3:$AI$104,4,FALSE) -> 339430 | AI21: =VLOOKUP(A21,'계산서(25하-천안)'!$X$3:$AI$104,2,FALSE) -> 국고 전액 | AJ21: =VLOOKUP(A21,'계산서(25하-천안)'!$X$3:$AI$104,8,FALSE) -> 0 | AK21: =VLOOKUP(A21,'계산서(25하-천안)'!$X$3:$AI$104,9,FALSE) -> 45973 | AL21: =VLOOKUP(A21,'계산서(25하-천안)'!$X$3:$AI$104,10,FALSE) -> 339430 | AM21: =VLOOKUP(A21,'계산서(25하-천안)'!$X$3:$AI$104,12,FALSE) -> 0
A22: H0207 | B22: 2025 | C22: 하반기 | D22: 고시물질 | E22: 천안 | F22: ="천-"&'25하-천안140'!A22 -> 천-147 | G22: 20 | H22: 15 | I22: 45909 | J22: 45909 | L22: 고유빈 | M22: 천안 | N22: 사단법인 천안제5일반산업단지입주기업체협의회 | O22: 10 | P22: 3128218355 | Q22: 31282183550 | R22: 홍상의 | T22: 충청남도 천안시 동남구 성남면 5산단3로 78 (대화리) | U22: 041-569-0264 | V22: 041-566-3840 | W22: 박갑수 | X22: 사원 | Y22: 010-3460-1265 | Z22: ca5sandan2@nate.com | AA22: 45931 | AB22: 고유빈 | AC22: ca5sandan3@nate.com | AD22: =VLOOKUP(A22,'계산서(25하-천안)'!$X$3:$AI$104,2,FALSE) -> 45974 | AF22: =VLOOKUP(A22,'계산서(25하-천안)'!$X$3:$AI$104,3,FALSE) -> 300000 | AG22: =VLOOKUP(A22,'계산서(25하-천안)'!$X$3:$AI$104,4,FALSE) -> 400000 | AI22: =VLOOKUP(A22,'계산서(25하-천안)'!$X$3:$AI$104,2,FALSE) -> 45974 | AJ22: =VLOOKUP(A22,'계산서(25하-천안)'!$X$3:$AI$104,8,FALSE) -> 300000 | AK22: =VLOOKUP(A22,'계산서(25하-천안)'!$X$3:$AI$104,9,FALSE) -> 45973 | AL22: =VLOOKUP(A22,'계산서(25하-천안)'!$X$3:$AI$104,10,FALSE) -> 400000 | AM22: =VLOOKUP(A22,'계산서(25하-천안)'!$X$3:$AI$104,12,FALSE) -> 0
A23: H0226 | B23: 2025 | C23: 하반기 | D23: 공정의 수시변경 | E23: 천안 | F23: ="천-"&'25하-천안140'!A23 -> 천-148 | G23: 21 | H23: 16 | I23: 45912 | J23: 45912 | L23: 강종구 | M23: 천안 | N23: (주) 현대자동차충청써비스 | O23: 100 | P23: 3128168805 | Q23: 31281688050 | R23: 김송 | T23: 충청남도 아산시 곡교천로125번길 35 (실옥동) | U23: 041-546-0992 | V23: 041-547-3396 | W23: 김사론 | Y23: 010-7138-1537 | Z23: mt3275@hanmail.net | AA23: 45931 | AB23: 강종구 | AC23: mt3275@hanmail.net | AD23: =VLOOKUP(A23,'계산서(25하-천안)'!$X$3:$AI$104,2,FALSE) -> 45912 | AF23: =VLOOKUP(A23,'계산서(25하-천안)'!$X$3:$AI$104,3,FALSE) -> 2350000 | AG23: =VLOOKUP(A23,'계산서(25하-천안)'!$X$3:$AI$104,4,FALSE) -> 0 | AI23: =VLOOKUP(A23,'계산서(25하-천안)'!$X$3:$AI$104,2,FALSE) -> 45912 | AJ23: =VLOOKUP(A23,'계산서(25하-천안)'!$X$3:$AI$104,8,FALSE) -> 2350000 | AK23: =VLOOKUP(A23,'계산서(25하-천안)'!$X$3:$AI$104,9,FALSE) -> 국고 X | AL23: =VLOOKUP(A23,'계산서(25하-천안)'!$X$3:$AI$104,10,FALSE) -> 0 | AM23: =VLOOKUP(A23,'계산서(25하-천안)'!$X$3:$AI$104,12,FALSE) -> 0
A24: H0348 | B24: 2025 | C24: 하반기 | D24: 고시물질 | E24: 천안 | F24: ="천-"&'25하-천안140'!A24 -> 천-149 | G24: 22 | H24: 17 | I24: 45912 | J24: 45912 | L24: 이주형 | M24: 성남 | N24: 동아하이테크 주식회사 | O24: 16 | P24: 1268639422 | Q24: 12686394220 | R24: 이우용, 이호일 | T24: 경기도 광주시 도척면 방도길 8-35 (유정리) | U24: 031-797-1003 | V24: 031-797-3001 | W24: 이용준 | X24: 과장 | Y24: 010-8920-2263 | Z24: yj_lee@dongah.biz | AA24: 45925 | AB24: 이주형 | AC24: yj_lee@dongah.biz | AD24: =VLOOKUP(A24,'계산서(25하-천안)'!$X$3:$AI$104,2,FALSE) -> 45930 | AF24: =VLOOKUP(A24,'계산서(25하-천안)'!$X$3:$AI$104,3,FALSE) -> 300000 | AG24: =VLOOKUP(A24,'계산서(25하-천안)'!$X$3:$AI$104,4,FALSE) -> 400000 | AI24: =VLOOKUP(A24,'계산서(25하-천안)'!$X$3:$AI$104,2,FALSE) -> 45930 | AJ24: =VLOOKUP(A24,'계산서(25하-천안)'!$X$3:$AI$104,8,FALSE) -> 300000 | AK24: =VLOOKUP(A24,'계산서(25하-천안)'!$X$3:$AI$104,9,FALSE) -> 45951 | AL24: =VLOOKUP(A24,'계산서(25하-천안)'!$X$3:$AI$104,10,FALSE) -> 400000 | AM24: =VLOOKUP(A24,'계산서(25하-천안)'!$X$3:$AI$104,12,FALSE) -> 0
A25: H0102 | B25: 2025 | C25: 하반기 | D25: 고시물질 | E25: 천안 | F25: ="천-"&'25하-천안140'!A25 -> 천-150 | G25: 23 | H25: 18 | I25: 45915 | J25: 45917 | L25: 한기문, 이주형, 강종구, 고유빈 | M25: 전주 | N25: 국립농업과학원 | O25: 1512 | P25: 1248301818 | Q25: 12483018180 | R25: 이상재 | T25: 전북특별자치도 완주군 이서면 농생명로 166 (금평리, 국립농업과학원) | U25: 063-238-2243 | V25: 063-238-3814 | W25: 안유미 | X25: 보건관리자 | Y25: 010-3194-8055 | Z25: dbal8055@korea.kr | AA25: 45946 | AB25: 이주형 | AC25: dbal8055@korea.kr | AD25: =VLOOKUP(A25,'계산서(25하-천안)'!$X$3:$AI$104,2,FALSE) -> 46015 | AF25: =VLOOKUP(A25,'계산서(25하-천안)'!$X$3:$AI$104,3,FALSE) -> 15500000 | AG25: =VLOOKUP(A25,'계산서(25하-천안)'!$X$3:$AI$104,4,FALSE) -> 0 | AI25: =VLOOKUP(A25,'계산서(25하-천안)'!$X$3:$AI$104,2,FALSE) -> 46015 | AJ25: =VLOOKUP(A25,'계산서(25하-천안)'!$X$3:$AI$104,8,FALSE) -> 15500000 | AK25: =VLOOKUP(A25,'계산서(25하-천안)'!$X$3:$AI$104,9,FALSE) -> 국고 X | AL25: =VLOOKUP(A25,'계산서(25하-천안)'!$X$3:$AI$104,10,FALSE) -> 0 | AM25: =VLOOKUP(A25,'계산서(25하-천안)'!$X$3:$AI$104,12,FALSE) -> 0
A26: H0406 | B26: 2025 | C26: 하반기 | D26: 공정의 수시변경 | E26: 천안 | F26: ="천-"&'25하-천안140'!A26 -> 천-151 | G26: 24 | H26: 19 | I26: 45916 | J26: 45916 | L26: 배윤민 | M26: 경기 | N26: 범일건설(주) 명인제약(주) 발안2공장 고형제동 증축공사 | O26: 48 | P26: 2148678417 | Q26: 21486784176 | R26: 설병덕 | T26: 경기도 화성시 향남읍 제약단지로 50 (하길리) | W26: 손기호 | X26: 부장 | Y26: 010-5237-7921 | Z26: bumil13@hanmail.net | AA26: 45944 | AB26: 배윤민 | AC26: bumil13@hanmail.net | AD26: =VLOOKUP(A26,'계산서(25하-천안)'!$X$3:$AI$104,2,FALSE) -> 45951 | AF26: =VLOOKUP(A26,'계산서(25하-천안)'!$X$3:$AI$104,3,FALSE) -> 1000000 | AG26: =VLOOKUP(A26,'계산서(25하-천안)'!$X$3:$AI$104,4,FALSE) -> 0 | AI26: =VLOOKUP(A26,'계산서(25하-천안)'!$X$3:$AI$104,2,FALSE) -> 45951 | AJ26: =VLOOKUP(A26,'계산서(25하-천안)'!$X$3:$AI$104,8,FALSE) -> 1000000 | AK26: =VLOOKUP(A26,'계산서(25하-천안)'!$X$3:$AI$104,9,FALSE) -> 국고 X | AL26: =VLOOKUP(A26,'계산서(25하-천안)'!$X$3:$AI$104,10,FALSE) -> 0 | AM26: =VLOOKUP(A26,'계산서(25하-천안)'!$X$3:$AI$104,12,FALSE) -> 0
A27: H0405 | B27: 2025 | C27: 하반기 | D27: 최초실시, 고시물질 | E27: 천안 | F27: ="천-"&'25하-천안140'!A27 -> 천-152 | G27: 25 | H27: 20 | I27: 45917 | J27: 45917 | L27: 강종구 | M27: 천안 | N27: 콜러벤처스인크 천안지점 | O27: 16 | P27: 2968400028 | Q27: 92438631521 | R27: KASHYAP JAIRAJ KAPADIA(카쉬얍제이라즈카파디아) | T27: 충청남도 천안시 서북구 직산읍 부송3길 61 (부송리, 노비타), B동 202호 | W27: 전우진 | X27: 프로 | Y27: 010-5491-1412 | Z27: woojin.jeon@kohler.com | AA27: 45943 | AB27: 강종구 | AC27: kraccountspayable@kohlerventures.com, woojin.jeon@kohler.com | AD27: =VLOOKUP(A27,'계산서(25하-천안)'!$X$3:$AI$104,2,FALSE) -> 45945 | AF27: =VLOOKUP(A27,'계산서(25하-천안)'!$X$3:$AI$104,3,FALSE) -> 300000 | AG27: =VLOOKUP(A27,'계산서(25하-천안)'!$X$3:$AI$104,4,FALSE) -> 1000000 | AI27: =VLOOKUP(A27,'계산서(25하-천안)'!$X$3:$AI$104,2,FALSE) -> 45945 | AJ27: =VLOOKUP(A27,'계산서(25하-천안)'!$X$3:$AI$104,8,FALSE) -> 300000 | AK27: =VLOOKUP(A27,'계산서(25하-천안)'!$X$3:$AI$104,9,FALSE) -> 45973 | AL27: =VLOOKUP(A27,'계산서(25하-천안)'!$X$3:$AI$104,10,FALSE) -> 1000000 | AM27: =VLOOKUP(A27,'계산서(25하-천안)'!$X$3:$AI$104,12,FALSE) -> 0
A28: H0288 | B28: 2025 | C28: 하반기 | D28: 소음85이상 | E28: 천안 | F28: ="천-"&'25하-천안140'!A28 -> 천-153 | G28: 26 | H28: 21 | I28: 45917 | J28: 45917 | L28: 고유빈 | M28: 천안 | N28: 동아하이테크 주식회사 2공장 | O28: 23 | P28: 1268639422 | Q28: 92231854931 | R28: 이우용, 이호일 | T28: 충청남도 천안시 서북구 성환읍 왕지1길 5 (율금리) | U28: 031-797-1003 | V28: 031-797-3001 | W28: 이용준, 이원국 | X28: 과장(본사) 차장(현장) | Y28: 010-8920-2263, 010-8928-0605 | Z28: wk0209@dongah.biz(현장) | AA28: 10월 16일 | AB28: 고유빈 | AC28: yj_lee@dongah.biz(본사) | AD28: =VLOOKUP(A28,'계산서(25하-천안)'!$X$3:$AI$104,2,FALSE) -> 45930 | AF28: =VLOOKUP(A28,'계산서(25하-천안)'!$X$3:$AI$104,3,FALSE) -> 100000 | AG28: =VLOOKUP(A28,'계산서(25하-천안)'!$X$3:$AI$104,4,FALSE) -> 366470 | AI28: =VLOOKUP(A28,'계산서(25하-천안)'!$X$3:$AI$104,2,FALSE) -> 45930 | AJ28: =VLOOKUP(A28,'계산서(25하-천안)'!$X$3:$AI$104,8,FALSE) -> 0 | AK28: =VLOOKUP(A28,'계산서(25하-천안)'!$X$3:$AI$104,9,FALSE) -> 45973 | AL28: =VLOOKUP(A28,'계산서(25하-천안)'!$X$3:$AI$104,10,FALSE) -> 366470 | AM28: =VLOOKUP(A28,'계산서(25하-천안)'!$X$3:$AI$104,12,FALSE) -> 0
A29: H0213 | B29: 2025 | C29: 하반기 | D29: 공정의 수시변경 | E29: 천안 | F29: ="천-"&'25하-천안140'!A29 -> 천-154 | G29: 27 | H29: 22 | I29: 45918 | J29: 45918 | L29: 강종구 | M29: 서산 | N29: 일성건설(주)삭선-원북 지방도 확포장공사 | O29: 34 | P29: 1058129640 | Q29: 10581296406 | R29: 백종탁 | T29: 충청남도 태안군 태안읍 원이로 77 (삭선리) | U29: 070-4924-0905 | V29: 041-674-0877 | W29: 최승현 | X29: 안전팀장 | Y29: 010-4616-5408 | Z29: 20230502@ilsungconst.co.kr | AA29: 45945 | AB29: 강종구 | AC29: 20230502@ilsungconst.co.kr | AD29: =VLOOKUP(A29,'계산서(25하-천안)'!$X$3:$AI$104,2,FALSE) -> 45953 | AF29: =VLOOKUP(A29,'계산서(25하-천안)'!$X$3:$AI$104,3,FALSE) -> 1700000 | AG29: =VLOOKUP(A29,'계산서(25하-천안)'!$X$3:$AI$104,4,FALSE) -> 0 | AI29: =VLOOKUP(A29,'계산서(25하-천안)'!$X$3:$AI$104,2,FALSE) -> 45953 | AJ29: =VLOOKUP(A29,'계산서(25하-천안)'!$X$3:$AI$104,8,FALSE) -> 1700000 | AK29: =VLOOKUP(A29,'계산서(25하-천안)'!$X$3:$AI$104,9,FALSE) -> 국고 X | AL29: =VLOOKUP(A29,'계산서(25하-천안)'!$X$3:$AI$104,10,FALSE) -> 0 | AM29: =VLOOKUP(A29,'계산서(25하-천안)'!$X$3:$AI$104,12,FALSE) -> 0
A30: H0346 | B30: 2025 | C30: 하반기 | D30: 공정의 수시변경 | E30: 천안 | F30: ="천-"&'25하-천안140'!A30 -> 천-155 | G30: 28 | H30: 23 | I30: 45918 | J30: 45918 | L30: 배윤민 | M30: 서산 | N30: 일성건설(주) 태안발전본부 공업용수관로(삭선-원북) 이설공사 | O30: 6 | P30: 1058129640 | Q30: 10581296406 | R30: 백종탁 | T30: 충청남도 태안군 태안읍 원이로 77 (삭선리) | U30: 070-4924-0905 | V30: 041-674-0877 | W30: 최승현 | X30: 안전팀장 | Y30: 010-4616-5408 | Z30: 20230502@ilsungconst.co.kr | AA30: 45945 | AB30: 배윤민 | AC30: 20230502@ilsungconst.co.kr | AD30: =VLOOKUP(A30,'계산서(25하-천안)'!$X$3:$AI$104,2,FALSE) -> 45953 | AF30: =VLOOKUP(A30,'계산서(25하-천안)'!$X$3:$AI$104,3,FALSE) -> 900000 | AG30: =VLOOKUP(A30,'계산서(25하-천안)'!$X$3:$AI$104,4,FALSE) -> 0 | AI30: =VLOOKUP(A30,'계산서(25하-천안)'!$X$3:$AI$104,2,FALSE) -> 45953 | AJ30: =VLOOKUP(A30,'계산서(25하-천안)'!$X$3:$AI$104,8,FALSE) -> 900000 | AK30: =VLOOKUP(A30,'계산서(25하-천안)'!$X$3:$AI$104,9,FALSE) -> 국고 X | AL30: =VLOOKUP(A30,'계산서(25하-천안)'!$X$3:$AI$104,10,FALSE) -> 0 | AM30: =VLOOKUP(A30,'계산서(25하-천안)'!$X$3:$AI$104,12,FALSE) -> 0
A31: H0368 | B31: 2025 | C31: 하반기 | D31: 공정의 수시변경 | E31: 천안 | F31: ="천-"&'25하-천안140'!A31 -> 천-156 | G31: 29 | H31: 24 | I31: 45919 | J31: 45919 | L31: 강종구 | M31: 서산 | N31: 일성건설(주) 삭선-원북간 상하수도관 이설공사 | O31: 6 | P31: 1058129640 | Q31: 10581296406 | R31: 백종탁 | T31: 충청남도 태안군 태안읍 삭선길 505 (삭선리) | U31: 070-4924-0905 | V31: 041-674-0877 | W31: 최승현 | X31: 안전팀장 | Y31: 010-4616-5408 | Z31: 20230502@ilsungconst.co.kr | AA31: 45945 | AB31: 강종구 | AC31: 20230502@ilsungconst.co.kr | AD31: =VLOOKUP(A31,'계산서(25하-천안)'!$X$3:$AI$104,2,FALSE) -> 45953 | AF31: =VLOOKUP(A31,'계산서(25하-천안)'!$X$3:$AI$104,3,FALSE) -> 900000 | AG31: =VLOOKUP(A31,'계산서(25하-천안)'!$X$3:$AI$104,4,FALSE) -> 0 | AI31: =VLOOKUP(A31,'계산서(25하-천안)'!$X$3:$AI$104,2,FALSE) -> 45953 | AJ31: =VLOOKUP(A31,'계산서(25하-천안)'!$X$3:$AI$104,8,FALSE) -> 900000 | AK31: =VLOOKUP(A31,'계산서(25하-천안)'!$X$3:$AI$104,9,FALSE) -> 국고 X | AL31: =VLOOKUP(A31,'계산서(25하-천안)'!$X$3:$AI$104,10,FALSE) -> 0 | AM31: =VLOOKUP(A31,'계산서(25하-천안)'!$X$3:$AI$104,12,FALSE) -> 0
A32: H0242 | B32: 2025 | C32: 하반기 | D32: 고시물질 | E32: 천안 | F32: ="천-"&'25하-천안140'!A32 -> 천-157 | G32: 30 | H32: 25 | I32: 45922 | J32: 45922 | L32: 이태환 | M32: 천안 | N32: 주식회사 엘에스이 | O32: 31 | P32: 1498101813 | Q32: 14981018130 | R32: 이관형 | T32: 충청남도 천안시 서북구 직산읍 4산단6길 22 (신갈리) | U32: 041-583-0110 | V32: 041-555-0933 | W32: 박기상 | X32: 부장 | Y32: 010-8964-7234 | Z32: kspark@lsglobal.co.kr | AA32: 45951 | AB32: 고유빈 | AC32: kspark@lsglobal.co.kr | AD32: =VLOOKUP(A32,'계산서(25하-천안)'!$X$3:$AI$104,2,FALSE) -> 45974 | AF32: =VLOOKUP(A32,'계산서(25하-천안)'!$X$3:$AI$104,3,FALSE) -> 1250000 | AG32: =VLOOKUP(A32,'계산서(25하-천안)'!$X$3:$AI$104,4,FALSE) -> 400000 | AI32: =VLOOKUP(A32,'계산서(25하-천안)'!$X$3:$AI$104,2,FALSE) -> 45974 | AJ32: =VLOOKUP(A32,'계산서(25하-천안)'!$X$3:$AI$104,8,FALSE) -> 1250000 | AK32: =VLOOKUP(A32,'계산서(25하-천안)'!$X$3:$AI$104,9,FALSE) -> 45973 | AL32: =VLOOKUP(A32,'계산서(25하-천안)'!$X$3:$AI$104,10,FALSE) -> 400000 | AM32: =VLOOKUP(A32,'계산서(25하-천안)'!$X$3:$AI$104,12,FALSE) -> 0
A33: H0307 | B33: 2025 | C33: 하반기 | D33: 고시물질 | E33: 천안 | F33: ="천-"&'25하-천안140'!A33 -> 천-158 | G33: 31 | H33: 26 | I33: 45922 | J33: 45922 | L33: 고유빈 | M33: 천안 | N33: (주)엘에스티 | O33: 15 | P33: 3128629753 | Q33: 31286297530 | R33: 이관형 | T33: 충청남도 천안시 서북구 직산읍 4산단4로 60, 씨동 1호 (모서리) | U33: 041-583-0110 | V33: 041-555-0933 | W33: 박기상 | X33: 부장 | Y33: 010-8964-7234 | Z33: kspark@lsglobal.co.kr | AA33: 45951 | AB33: 고유빈 | AC33: kspark@lsglobal.co.kr | AD33: =VLOOKUP(A33,'계산서(25하-천안)'!$X$3:$AI$104,2,FALSE) -> 45974 | AF33: =VLOOKUP(A33,'계산서(25하-천안)'!$X$3:$AI$104,3,FALSE) -> 600000 | AG33: =VLOOKUP(A33,'계산서(25하-천안)'!$X$3:$AI$104,4,FALSE) -> 400000 | AI33: =VLOOKUP(A33,'계산서(25하-천안)'!$X$3:$AI$104,2,FALSE) -> 45974 | AJ33: =VLOOKUP(A33,'계산서(25하-천안)'!$X$3:$AI$104,8,FALSE) -> 0 | AK33: =VLOOKUP(A33,'계산서(25하-천안)'!$X$3:$AI$104,9,FALSE) -> 45973 | AL33: =VLOOKUP(A33,'계산서(25하-천안)'!$X$3:$AI$104,10,FALSE) -> 400000 | AM33: =VLOOKUP(A33,'계산서(25하-천안)'!$X$3:$AI$104,12,FALSE) -> 0
A34: H0137 | B34: 2025 | C34: 하반기 | D34: 고시물질 | E34: 천안 | F34: ="천-"&'25하-천안140'!A34 -> 천-159 | G34: 32 | H34: 27 | I34: 45922 | J34: 45922 | L34: 이주형 | M34: 천안 | N34: 성일테크(주)당진공장 | O34: 6 | P34: 4178133090 | Q34: 92126827491 | R34: 황일곤 | T34: 충청남도 당진시 석문면 산단3로2길 19 (통정리) | U34: 070-4250-3949 | V34: 041-354-1503 | W34: 김보성 | X34: 과장 | Y34: 010-9146-6015 | Z34: sighwang@hanmail.net | AA34: 45951 | AB34: 이주형 | AC34: sighwang@hanmail.net | AD34: =VLOOKUP(A34,'계산서(25하-천안)'!$X$3:$AI$104,2,FALSE) -> 45951 | AF34: =VLOOKUP(A34,'계산서(25하-천안)'!$X$3:$AI$104,3,FALSE) -> 600000 | AG34: =VLOOKUP(A34,'계산서(25하-천안)'!$X$3:$AI$104,4,FALSE) -> 400000 | AI34: =VLOOKUP(A34,'계산서(25하-천안)'!$X$3:$AI$104,2,FALSE) -> 45951 | AJ34: =VLOOKUP(A34,'계산서(25하-천안)'!$X$3:$AI$104,8,FALSE) -> 600000 | AK34: =VLOOKUP(A34,'계산서(25하-천안)'!$X$3:$AI$104,9,FALSE) -> 45973 | AL34: =VLOOKUP(A34,'계산서(25하-천안)'!$X$3:$AI$104,10,FALSE) -> 400000 | AM34: =VLOOKUP(A34,'계산서(25하-천안)'!$X$3:$AI$104,12,FALSE) -> 0
A35: H0260 | B35: 2025 | C35: 하반기 | D35: 고시물질 | E35: 천안 | F35: ="천-"&'25하-천안140'!A35 -> 천-[[ | G35: 33 | H35: 28 | I35: 45923 | J35: 45923 | L35: 한기문, 고유빈, 배윤민 | M35: 보령 | N35: 국립해양생물자원관 | O35: 260 | P35: 1378210048 | Q35: 13782100480 | R35: 김현태 | T35: 충청남도 서천군 장항읍 장산로101번길 75 (송림리, 국립해양생물자원관) | U35: 041-950-0680 | V35: 041-950-0682 | W35: 이예솔 | X35: 보건관리자 | Y35: 010-3386-6325 | Z35: leeyesol95@mabik.re.kr | AA35: 45952 | AB35: 한기문 | AC35: 0 | AD35: =VLOOKUP(A35,'계산서(25하-천안)'!$X$3:$AI$104,2,FALSE) -> 45960 | AF35: =VLOOKUP(A35,'계산서(25하-천안)'!$X$3:$AI$104,3,FALSE) -> 9700000 | AG35: =VLOOKUP(A35,'계산서(25하-천안)'!$X$3:$AI$104,4,FALSE) -> 0 | AI35: =VLOOKUP(A35,'계산서(25하-천안)'!$X$3:$AI$104,2,FALSE) -> 45960 | AJ35: =VLOOKUP(A35,'계산서(25하-천안)'!$X$3:$AI$104,8,FALSE) -> 9700000 | AK35: =VLOOKUP(A35,'계산서(25하-천안)'!$X$3:$AI$104,9,FALSE) -> 국고 X | AL35: =VLOOKUP(A35,'계산서(25하-천안)'!$X$3:$AI$104,10,FALSE) -> 0 | AM35: =VLOOKUP(A35,'계산서(25하-천안)'!$X$3:$AI$104,12,FALSE) -> 0
A36: H0407 | B36: 2025 | C36: 하반기 | D36: 최초실시, 공정의 수시변경 | E36: 천안 | F36: ="천-"&'25하-천안140'!A36 -> 천-161 | G36: 34 | H36: 28 | I36: 45923 | J36: 45923 | L36: 강종구 | M36: 천안 | N36: (주) 광전사 천안 스마트그린산단 통합관제센터 스마트횡단보도 설치 | O36: 4 | P36: 3128154505 | Q36: 31281545056 | R36: 박현석 | T36: 충청남도 천안시 서북구 3공단6로 86-9 제3일반산업단지 | W36: 정동주 | Y36: 010-8883-7115 | Z36: lwt3let3@naver.com | AA36: 45951 | AB36: 강종구 | AC36: kjs28855@hanmail.net | AD36: =VLOOKUP(A36,'계산서(25하-천안)'!$X$3:$AI$104,2,FALSE) -> 국고 전액 | AF36: =VLOOKUP(A36,'계산서(25하-천안)'!$X$3:$AI$104,3,FALSE) -> 0 | AG36: =VLOOKUP(A36,'계산서(25하-천안)'!$X$3:$AI$104,4,FALSE) -> 1000000 | AI36: =VLOOKUP(A36,'계산서(25하-천안)'!$X$3:$AI$104,2,FALSE) -> 국고 전액 | AJ36: =VLOOKUP(A36,'계산서(25하-천안)'!$X$3:$AI$104,8,FALSE) -> 0 | AK36: =VLOOKUP(A36,'계산서(25하-천안)'!$X$3:$AI$104,9,FALSE) -> 45973 | AL36: =VLOOKUP(A36,'계산서(25하-천안)'!$X$3:$AI$104,10,FALSE) -> 1000000 | AM36: =VLOOKUP(A36,'계산서(25하-천안)'!$X$3:$AI$104,12,FALSE) -> 0
A37: H0267 | B37: 2025 | C37: 하반기 | E37: 천안 | F37: ="천-"&'25하-천안140'!A37 -> 천-162 | G37: 35 | H37: 29 | I37: 45925 | J37: 45925 | L37: 고유빈 | M37: 서산 | N37: 태안군농협쌀조합공동사업법인 | O37: 10 | P37: 4588602308 | Q37: 45886023080 | R37: 한영헌 | T37: 충청남도 태안군 태안읍 송암로 30-24 (남산리) | U37: 041-675-8931 | V37: 041-675-8934 | W37: 이유진 | Y37: 010-9095-6411 | Z37: nh481141-1@nonghyup.com | AA37: 10월 21일 | AB37: 고유빈 | AC37: nh481141-1@nonghyup.com | AD37: =VLOOKUP(A37,'계산서(25하-천안)'!$X$3:$AI$104,2,FALSE) -> 45974 | AF37: =VLOOKUP(A37,'계산서(25하-천안)'!$X$3:$AI$104,3,FALSE) -> 300000 | AG37: =VLOOKUP(A37,'계산서(25하-천안)'!$X$3:$AI$104,4,FALSE) -> 400000 | AI37: =VLOOKUP(A37,'계산서(25하-천안)'!$X$3:$AI$104,2,FALSE) -> 45974 | AJ37: =VLOOKUP(A37,'계산서(25하-천안)'!$X$3:$AI$104,8,FALSE) -> 300000 | AK37: =VLOOKUP(A37,'계산서(25하-천안)'!$X$3:$AI$104,9,FALSE) -> 45973 | AL37: =VLOOKUP(A37,'계산서(25하-천안)'!$X$3:$AI$104,10,FALSE) -> 400000 | AM37: =VLOOKUP(A37,'계산서(25하-천안)'!$X$3:$AI$104,12,FALSE) -> 0
A38: H0172 | B38: 2025 | C38: 하반기 | E38: 천안 | F38: ="천-"&'25하-천안140'!A38 -> 천-163 | G38: 36 | H38: 30 | I38: 45925 | J38: 45925 | L38: 이주형 | M38: 천안 | N38: 주식회사 소닉스비오엠 | O38: 30 | P38: 1078809580 | Q38: 10788095800 | R38: 류병일 | T38: 충청남도 천안시 서북구 2공단3로 59 (업성동) | U38: 041-585-5701 | V38: 041-585-5703 | W38: 김성수 | X38: 부사장 | Y38: 010-5460-3453 | Z38: kss1014kr@naver.com | AA38: 45954 | AB38: 이주형 | AC38: kss1014kr@naver.com | AD38: =VLOOKUP(A38,'계산서(25하-천안)'!$X$3:$AI$104,2,FALSE) -> 45954 | AF38: =VLOOKUP(A38,'계산서(25하-천안)'!$X$3:$AI$104,3,FALSE) -> 200000 | AG38: =VLOOKUP(A38,'계산서(25하-천안)'!$X$3:$AI$104,4,FALSE) -> 400000 | AI38: =VLOOKUP(A38,'계산서(25하-천안)'!$X$3:$AI$104,2,FALSE) -> 45954 | AJ38: =VLOOKUP(A38,'계산서(25하-천안)'!$X$3:$AI$104,8,FALSE) -> 200000 | AK38: =VLOOKUP(A38,'계산서(25하-천안)'!$X$3:$AI$104,9,FALSE) -> 45973 | AL38: =VLOOKUP(A38,'계산서(25하-천안)'!$X$3:$AI$104,10,FALSE) -> 400000 | AM38: =VLOOKUP(A38,'계산서(25하-천안)'!$X$3:$AI$104,12,FALSE) -> 0
A39: H0163 | B39: 2025 | C39: 하반기 | D39: 고시물질 | E39: 천안 | F39: ="천-"&'25하-천안140'!A39 -> 천-164 | G39: 37 | H39: 31 | I39: 45926 | J39: 45926 | L39: 한기문, 강종구, 배윤민 | M39: 전주 | N39: 국립축산과학원 | O39: 317 | P39: 1248301711 | Q39: 12483017110 | R39: 임기순 | T39: 전북특별자치도 완주군 이서면 콩쥐팥쥐로 1500 (금평리, 국립축산과학원) | U39: 063-238-7178 | V39: 063-238-7174 | W39: 김은혜 | X39: 보건관리자 | Y39: 010-9905-4498 | Z39: geace25@korea.kr | AA39: 45952 | AB39: 한기문 | AC39: euni2698@korea.kr | AD39: =VLOOKUP(A39,'계산서(25하-천안)'!$X$3:$AI$104,2,FALSE) -> 45980 | AF39: =VLOOKUP(A39,'계산서(25하-천안)'!$X$3:$AI$104,3,FALSE) -> 4700000 | AG39: =VLOOKUP(A39,'계산서(25하-천안)'!$X$3:$AI$104,4,FALSE) -> - | AI39: =VLOOKUP(A39,'계산서(25하-천안)'!$X$3:$AI$104,2,FALSE) -> 45980 | AJ39: =VLOOKUP(A39,'계산서(25하-천안)'!$X$3:$AI$104,8,FALSE) -> 4700000 | AK39: =VLOOKUP(A39,'계산서(25하-천안)'!$X$3:$AI$104,9,FALSE) -> 국고 X | AL39: =VLOOKUP(A39,'계산서(25하-천안)'!$X$3:$AI$104,10,FALSE) -> 0 | AM39: =VLOOKUP(A39,'계산서(25하-천안)'!$X$3:$AI$104,12,FALSE) -> 0
A40: H0403 | B40: 2025 | C40: 하반기 | D40: 최초실시, 고시물질 | E40: 천안 | F40: ="천-"&'25하-천안140'!A40 -> 천-165 | G40: 38 | H40: 32 | I40: 45930 | J40: 45930 | L40: 한기문 | M40: 천안 | N40: 주식회사 알디솔루션 천안공장 | O40: 15 | P40: 5678701631 | Q40: 92540861161 | R40: 손일 | T40: 충청남도 천안시 서북구 입장면 망향로 1225 (독정리) | U40: 1611-2837 | V40: 0503-8379-5588 | W40: 권유안 | X40: 팀장 | Y40: 010-5554-4922 | Z40: kya052@rdsglobal.net | AA40: 45954 | AB40: 한기문 | AC40: 0 | AD40: =VLOOKUP(A40,'계산서(25하-천안)'!$X$3:$AI$104,2,FALSE) -> 45954 | AF40: =VLOOKUP(A40,'계산서(25하-천안)'!$X$3:$AI$104,3,FALSE) -> 1300000 | AG40: =VLOOKUP(A40,'계산서(25하-천안)'!$X$3:$AI$104,4,FALSE) -> 1000000 | AI40: =VLOOKUP(A40,'계산서(25하-천안)'!$X$3:$AI$104,2,FALSE) -> 45954 | AJ40: =VLOOKUP(A40,'계산서(25하-천안)'!$X$3:$AI$104,8,FALSE) -> 1300000 | AK40: =VLOOKUP(A40,'계산서(25하-천안)'!$X$3:$AI$104,9,FALSE) -> 45973 | AL40: =VLOOKUP(A40,'계산서(25하-천안)'!$X$3:$AI$104,10,FALSE) -> 1000000 | AM40: =VLOOKUP(A40,'계산서(25하-천안)'!$X$3:$AI$104,12,FALSE) -> 0
...

Sheet 사업장정보
A1: 순번 | B1: 사업장명 | C1: 대표자명 | D1: 사업자번호 | E1: 코드 | F1: 우편번호 | G1: 주소1 | H1: 주소2 | I1: 전화번호 | J1: 팩스번호 | K1: 업태 | L1: 업종코드 | M1: 업종 | N1: 관할청코드 | O1: 관할청 | P1: 주생산품 | Q1: 남근로수 | R1: 여근로수 | S1: 관리번호 | T1: 계산서 메일 | U1: 계산서 담당 | V1: 직위 | W1: 연락처 | X1: 년도 | Y1: 등록일 | Z1: 향후측정예상일 | AA1: 비고
A2: 9 | B2: (유)대덕현대서비스 | C2: 김기송, 김경호 | D2: 3058153605 | E2: H0036 | F2: 34357 | G2: 대전광역시 대덕구 신탄진로 375 (와동) | I2: 042-625-6600 | J2: 042-625-6601 | L2: 95211 | M2: 자동차 종합 수리업 | N2: 7000 | O2: 대전지방고용노동청 | P2: 차량수리 및 도장업 | Q2: 29 | R2: 0 | T2: daehyungcv@hanmail.net | U2: 김정무 | V2: 부장 | W2: 010-3412-4052 | X2: 2023 | Y2: 2023-01-31
A3: 10 | B3: (자)신화소방 Camp Project 현장 | C3: 배남진 | D3: 4178103747 | E3: H0265 | F3: 54008 | G3: 전북특별자치도 군산시 임해로 49 (소룡동, 넥세온코리아유한회사) | I3: 061-652-2217 | J3: 061-652-2219 | L3: 41122 | M3: 제조업 및 유사 산업용 건물 건설업 | N3: 6130 | O3: 광주지방고용노동청 군산지청 | P3: 소방공사 | Q3: 5 | R3: 0 | T3: bnj2217@hanmail.net | U3: 강준규 | V3: 이사 | W3: 010-9299-4039 | X3: 2024 | Y3: 2024-05-08
A4: 11 | B4: (자)유승기업 | C4: 장정민 | D4: 3148100193 | E4: H0138 | F4: 35267 | G4: 대전광역시 서구 계룡로 510 (탄방동) | I4: 042-523-0033 | J4: 042-527-7611 | L4: 95211 | M4: 자동차 종합 수리업 | N4: 7000 | O4: 대전지방고용노동청 | P4: 차량수리 및 도장업 | Q4: 28 | R4: 0 | T4: ys0033@hometax.go.kr | U4: 이종대 | V4: 부장 | W4: 010-3591-3291 | X4: 2023 | Y4: 2023-03-17
A5: 12 | B5: (주) 광전사 천안 스마트그린산단 통합관제센터 스마트횡단보도 설치 | C5: 박현석 | D5: 3128154505 | E5: H0407 | F5: 31085 | G5: 충청남도 천안시 서북구 3공단6로 86-9 제3일반산업단지 일대 (차암동) | I5: 041-578-2885 | J5: 041-578-5559 | L5: 42311 | M5: 일반전기 공사업 | N5: 7210 | O5: 대전지방고용노동청 천안지청 | P5: 전기공사, 정보통신공사 | Q5: 4 | R5: 0 | T5: kjs28855@hanmail.net | X5: 2025 | Y5: 2025-09-23
A6: 13 | B6: (주) 국보디자인 설해원 설해수림 인테리어 공사 C공구 | C6: 황창연, 김민기 | D6: 1028122615 | E6: H0352 | F6: 25042 | G6: 강원특별자치도 양양군 손양면 공항로 230 (동호리, 설해원) | L6: 42412 | M6: 도배, 실내장식 및 내장 목공사업 | N6: 2130 | O6: 중부지방고용노동청 강릉지청 | P6: 인테리어 공사 | Q6: 0 | R6: 0 | T6: kukbo1@ikukbo.com | X6: 2025 | Y6: 2025-03-21
A7: 14 | B7: (주) 대진자동차공업사 | C7: 이숙자 | D7: 3148624512 | E7: H0033 | F7: 34314 | G7: 대전광역시 대덕구 신탄진로756번안길 79 (신탄진동) | I7: 042-933-1282 | J7: 042-934-1284 | L7: 95211 | M7: 자동차 종합 수리업 | N7: 7000 | O7: 대전지방고용노동청 | P7: 차량수리 및 도장업 | Q7: 14 | R7: 0 | T7: daejin24512@hanmail.net | U7: 이숙자 | V7: 대표 | W7: 010-9948-5467 | X7: 2023 | Y7: 2023-01-31
A8: 15 | B8: (주) 두산금속 | C8: 김영이 | D8: 1408113291 | E8: H0401 | F8: 15112 | G8: 경기도 시흥시 마유로82번길 52 (정왕동) | I8: 031-432-0783 | J8: 031-432-0785 | L8: 25929 | M8: 그 외 기타 금속가공업 | N8: 5140 | O8: 중부지방고용노동청 안산지청 | P8: 소방기구, 충전기함 | Q8: 22 | R8: 0 | X8: 2025 | Y8: 2025-08-26
A9: 16 | B9: (주) 레오플 23-충-공-5D시설공사(군경대대생활관 증축) | C9: 권철진 | D9: 3088137832 | E9: H0252 | F9: 32024 | G9: 충청남도 서산시 해미면 신성로 330-1 (기지리) | L9: 41111 | M9: 단독 주택 건설업 | N9: 7230 | O9: 대전지방고용노동청 서산지청 | P9: 건설 | Q9: 7 | R9: 0 | T9: leople@leople.co.kr | X9: 2024 | Y9: 2024-04-04
A10: 17 | B10: (주) 레오플 24-D-OO부대 간부숙소 리모델링 시설공사 | C10: 권철진 | D10: 3088137832 | E10: H0371 | F10: 32801 | G10: 충청남도 계룡시 신도안면 신도안2길 96 (남선리, 군인아파트) | I10: 044-864-8122 | J10: 044-864-8124 | L10: 41119 | M10: 기타 공동 주택 건설업 | N10: 7000 | O10: 대전지방고용노동청 | P10: 건설 | Q10: 3 | R10: 0 | T10: LEOPLE@hometax.go.kr | U10: 김동혁 | V10: 소장 | W10: 010-4462-2029 | X10: 2025 | Y10: 2025-05-02
A11: 18 | B11: (주) 보성산업 | C11: 최정운 | D11: 3128136827 | E11: H0385 | F11: 31210 | G11: 충청남도 천안시 동남구 신방남부길 3 (신방동, 보성산업) | I11: 041-577-6294 | J11: 041-576-2694 | L11: 41229 | M11: 기타 토목시설물 건설업 | N11: 7210 | O11: 대전지방고용노동청 천안지청 | P11: 철물공사, 조립식구조물 | Q11: 0 | R11: 0 | T11: bosung6294@daum.net | X11: 2025 | Y11: 2025-06-09
A12: 19 | B12: (주) 부현전기 쿠팡 CHA 6FC Ph2 전기공사 | C12: 김홍수 | D12: 1188121173 | E12: H0424 | F12: 31025 | G12: 충청남도 천안시 서북구 입장면 용정도하길 181 (용정리) | L12: 42311 | M12: 일반전기 공사업 | N12: 7210 | O12: 대전지방고용노동청 천안지청 | P12: 전기공사업, 정보통신공사업 | Q12: 0 | R12: 0 | T12: kyong16@hometax.go.kr | X12: 2025 | Y12: 2025-12-04
A13: 20 | B13: (주) 운성모터스 | C13: 김재경 | D13: 3058176350 | E13: H0048 | F13: 34426 | G13: 대전광역시 대덕구 한밭대로 1088 (중리동) | I13: 042-624-4443 | J13: 042-628-4443 | L13: 95211 | M13: 자동차 종합 수리업 | N13: 7000 | O13: 대전지방고용노동청 | P13: 차량수리 및 도장업 | Q13: 14 | R13: 0 | T13: qhfka1401@naver.com | U13: 오관석 | V13: 부장 | W13: 010-6847-9291 | X13: 2023 | Y13: 2023-01-31
A14: 21 | B14: (주) 유성 | C14: 정성욱 | D14: 3128188679 | E14: H0248 | F14: 31032 | G14: 충청남도 천안시 서북구 직산읍 군수1길 96 | I14: 041-588-8817 | J14: 041-588-8819 | L14: 29133 | M14: 탭, 밸브 및 유사 장치 제조업 | N14: 7210 | O14: 대전지방고용노동청 천안지청 | P14: 밸브 | Q14: 0 | R14: 0 | T14: ys8817@yusungvalve.co.kr | U14: 이재원 | V14: 주임 | W14: 010-5226-3071 | X14: 2024 | Y14: 2024-03-29
A15: 22 | B15: (주) 제이앤지 | C15: 이동근 | D15: 3128603660 | E15: H0167 | F15: 31532 | G15: 충청남도 아산시 온천대로1122번길 17 (득산동) | I15: 041-545-0637 | J15: 041-545-0638 | L15: 30399 | M15: 그 외 자동차용 신품 부품 제조업 | N15: 7210 | O15: 대전지방고용노동청 천안지청 | P15: 자동차 부품 | Q15: 0 | R15: 0 | T15: ljb1072@daum.net | X15: 2023 | Y15: 2023-05-04
A16: 23 | B16: (주) 제일엠앤에스 천안CF동 극판 M라인 PD,믹싱설비,분체제작설치 | C16: 이효원, 이영진 | D16: 1248114298 | E16: H0357 | F16: 31086 | G16: 충청남도 천안시 서북구 번영로 467 (성성동, 삼성SDI(주)) | L16: 41225 | M16: 산업생산시설 종합건설업 | N16: 7210 | O16: 대전지방고용노동청 천안지청 | P16: 기계장치 공사 | Q16: 80 | R16: 0 | T16: jh.kim3@jeilm.co.kr | U16: 김종하 | V16: 매니저 | W16: 010-7272-8811 | X16: 2025 | Y16: 2025-04-01
A17: 24 | B17: (주) 제효 마정리 단독주택 신축공사 | C17: 이백화 | D17: 1138144676 | E17: H0310 | F17: 31028 | G17: 충청남도 천안시 서북구 직산읍 금곡로 317 (마정리) | L17: 41111 | M17: 단독 주택 건설업 | N17: 7210 | O17: 대전지방고용노동청 천안지청 | P17: 건설 | Q17: 4 | R17: 0 | T17: jsk303@naver.com | X17: 2024 | Y17: 2024-11-06
A18: 25 | B18: (주) 현대자동차충청써비스 | C18: 김송 | D18: 3128168805 | E18: H0226 | F18: 31501 | G18: 충청남도 아산시 곡교천로125번길 35(실옥동) | I18: 041-546-0992 | J18: 041-547-3396 | L18: 95211 | M18: 자동차 종합 수리업 | N18: 7210 | O18: 대전지방고용노동청 천안지청 | P18: 차량수리 및 도장업 | Q18: 99 | R18: 0 | T18: mt3275@hanmail.net | X18: 2023 | Y18: 2023-11-09
A19: 26 | B19: (주)1급금호자동차정비 | C19: 김영환 | D19: 3058165912 | E19: H0037 | F19: 34357 | G19: 대전광역시 대덕구 신탄진로 319 (와동) | I19: 042-627-0020 | J19: 042-627-0028 | L19: 95211 | M19: 자동차 종합 수리업 | N19: 7000 | O19: 대전지방고용노동청 | P19: 차량수리 및 도장업 | Q19: 10 | R19: 0 | T19: kh0020@hanmail.net | U19: 윤현성 | V19: 공장장 | W19: 010-2987-1661 | X19: 2023 | Y19: 2023-01-31
A20: 27 | B20: (주)1급동부자동차공업사 | C20: 임진수 | D20: 3058185432 | E20: H0190 | F20: 34700 | G20: 대전광역시 동구 대종로 15 (대성동) | I20: 042-272-1500 | J20: 042-271-8287 | L20: 95211 | M20: 자동차 종합 수리업 | N20: 7000 | O20: 대전지방고용노동청 | P20: 차량수리 및 도장업 | Q20: 0 | R20: 0 | T20: db8287@hanmail.net | U20: 임진수 | V20: 대표 | W20: 010-5408-5339 | X20: 2023 | Y20: 2023-07-04
A21: 28 | B21: (주)21세기자동차정비 | C21: 조영숙 | D21: 3148141141 | E21: H0155 | F21: 35283 | G21: 대전광역시 서구 대덕대로 67 (괴정동) | I21: 042-532-2121 | J21: 042-531-5465 | L21: 95211 | M21: 자동차 종합 수리업 | N21: 7000 | O21: 대전지방고용노동청 | P21: 차량수리 및 도장업 | Q21: 12 | R21: 0 | X21: 2023 | Y21: 2023-04-17
A22: 29 | B22: (주)거화 | C22: 이대곤 | D22: 1378144615 | E22: H0364 | F22: 21629 | G22: 인천광역시 남동구 남동대로 383 (남촌동) | I22: 032-567-7456 | J22: 032-567-7459 | L22: 29199 | M22: 그 외 기타 일반목적용 기계 제조업 | N22: 5000 | O22: 중부지방고용노동청 | P22: 열교환기 | Q22: 25 | R22: 0 | X22: 2025 | Y22: 2025-04-11
A23: 30 | B23: (주)경동원 아산공장 | C23: 김종욱 | D23: 2208113641 | E23: H0217 | F23: 31402 | G23: 충청남도 아산시 영인면 아산호로 331 (백석포리) | I23: 041-539-8181 | J23: 041-543-8119 | L23: 23999 | M23: 그 외 기타 분류 안된 비금속 광물제품 제조업 | N23: 7210 | O23: 대전지방고용노동청 천안지청 | P23: 퍼라이트, 내화단열재, 보일러제품 등 | Q23: 121 | R23: 0 | T23: sju04093@kdiwin.com | U23: 임상윤 | V23: 매니져 | W23: 010-9734-5108 | X23: 2023 | Y23: 2023-10-05
A24: 31 | B24: (주)경일모터스 | C24: 박정분 | D24: 2788600757 | E24: H0096 | F24: 34987 | G24: 대전광역시 중구 유등천동로 324 (산성동) | I24: 042-584-2929 | J24: 042-586-0776 | L24: 95211 | M24: 자동차 종합 수리업 | N24: 7000 | O24: 대전지방고용노동청 | P24: 차량수리 및 도장업 | Q24: 13 | R24: 0 | T24: ki5842929@naver.com | U24: 안정환 | V24: 부장 | W24: 010-9282-1959 | X24: 2023 | Y24: 2023-01-31
A25: 32 | B25: (주)경화 청주지점 | C25: 정성곤 | D25: 3178505647 | E25: H0237 | F25: 28174 | G25: 충청북도 청주시 흥덕구 강내면 황탄리길 211 (황탄리) | I25: 043-232-9009 | J25: 043-232-9018 | L25: 18119 | M25: 기타 인쇄업 | N25: 7110 | O25: 대전지방고용노동청 청주지청 | P25: 후렉소용 제판 | Q25: 4 | R25: 0 | T25: khcj9009@naver.com | U25: 이정희 | W25: 010-3740-8233 | X25: 2024 | Y25: 2024-02-20
A26: 33 | B26: (주)고속모터스 | C26: 전원식 | D26: 3058164437 | E26: H0050 | F26: 34573 | G26: 대전광역시 동구 합내로 73 (가양동) | I26: 042-627-4972 | J26: 042-627-4949 | L26: 95211 | M26: 자동차 종합 수리업 | N26: 7000 | O26: 대전지방고용노동청 | P26: 차량수리 및 도장업 | Q26: 13 | R26: 0 | T26: jun9733@daum.net | U26: 정현숙 | V26: 담당 | W26: 010-4739-7282 | X26: 2023 | Y26: 2023-01-31
A27: 34 | B27: (주)관저자동차공업 | C27: 김희동 | D27: 5248701151 | E27: H0090 | F27: 34223 | G27: 대전광역시 유성구 계백로 937 (원내동) | I27: 042-544-2222 | J27: 042-544-4041 | L27: 95211 | M27: 자동차 종합 수리업 | N27: 7000 | O27: 대전지방고용노동청 | P27: 차량수리 및 도장업 | Q27: 14 | R27: 0 | T27: 8800sun@hometax.go.kr | U27: 백성수 | V27: 부장 | W27: 010-2694-0363 | X27: 2023 | Y27: 2023-01-31
A28: 35 | B28: (주)다정공업사 | C28: 김효남 | D28: 3578602873 | E28: H0040 | F28: 34352 | G28: 대전광역시 대덕구 신탄진로 1, 정비동 2층 (읍내동, 대한통운) | I28: 042-626-3884 | J28: 042-626-3885 | L28: 95211 | M28: 자동차 종합 수리업 | N28: 7000 | O28: 대전지방고용노동청 | P28: 차량수리 및 도장업 | Q28: 5 | R28: 0 | T28: dajung3885@naver.com | U28: 김효남 | V28: 김효남 | W28: 010-2050-3884 | X28: 2023 | Y28: 2023-01-31
A29: 36 | B29: (주)단해 | C29: 엄재웅 | D29: 3028502857 | E29: H0185 | F29: 29118 | G29: 충청북도 영동군 추풍령면 신안로 210-4 (지봉리, 단해공장) | I29: 043-742-7788 | J29: 043-742-9841 | L29: 29133 | M29: 탭, 밸브 및 유사 장치 제조업 | N29: 7210 | O29: 대전지방고용노동청 천안지청 | P29: 기타 공기조절장치 및 부품 | Q29: 28 | R29: 0 | T29: 3tanhay@hometax.go.kr | U29: 이기훈 | V29: 대리 | W29: 010-5716-6650 | X29: 2023 | Y29: 2023-06-27
A30: 37 | B30: (주)대명기전 보령화력본부 저탄장 옥내화사업 소방공사 | C30: 박태주 | D30: 40986183756 | E30: H0298 | F30: 33408 | G30: 충청남도 보령시 오천면 오천해안로 89-37 (오포리) | L30: 42311 | M30: 일반 전기 공사업 | N30: 7220 | O30: 대전지방고용노동청 보령지청 | P30: 건설 | Q30: 0 | R30: 0 | T30: majuk731@gmail.com | U30: 배진호 | W30: 010-5633-6739 | X30: 2024 | Y30: 2024-09-11
A31: 38 | B31: (주)대전공업사 | C31: 전준식 | D31: 3068119861 | E31: H0023 | F31: 34344 | G31: 대전광역시 대덕구 벚꽃길 86 (상서동) | I31: 042-932-9733 | J31: 042-931-8912 | L31: 95211 | M31: 자동차 종합 수리업 | N31: 7000 | O31: 대전지방고용노동청 | P31: 차량수리 및 도장업 | Q31: 17 | R31: 0 | T31: dj9733@homtax.go.kr | U31: 이해연 | V31: 공장장 | W31: 010-3365-0929 | X31: 2023 | Y31: 2023-01-31
A32: 39 | B32: (주)대화정공 | C32: 박제화 | D32: 3128131399 | E32: H0174 | F32: 31032 | G32: 충청남도 천안시 서북구 직산읍 군수1길 206-17 (군서리, 대화정공) | I32: 041-588-5600 | J32: 041-588-5603 | L32: 30320 | M32: 자동차 차체용 신품 부품 제조업 | N32: 7210 | O32: 대전지방고용노동청 천안지청 | P32: 자동차 부품 | Q32: 0 | R32: 0 | T32: dhwapu@hanmail.net | U32: 김지철 | V32: 총괄 수석부장 | W32: 010-3001-2442 | X32: 2023 | Y32: 2023-05-23
A33: 40 | B33: (주)동승 JW메리어트 동대문스퀘어서울 | C33: 정종환, 양병덕 | D33: 5888500598 | E33: H0147 | F33: 03198 | G33: 서울특별시 종로구 청계천로 279 (종로6가) | I33: 02-2276-3174 | J33: 02-2276-3001 | L33: 55101 | M33: 호텔업 | N33: 2000 | O33: 서울지방고용노동청 | P33: 숙박서비스 | Q33: 190 | R33: 0 | X33: 2023 | Y33: 2023-04-04
A34: 41 | B34: (주)동양산업이엔지 천안~아산(용곡지하차도)구간 배관이설공사 | C34: 전성오 | D34: 6108167544 | E34: H0308 | F34: 31201 | G34: 충청남도 천안시 동남구 용수골길 10-6 일원 (용곡동) | L34: 41229 | M34: 기타 토목시설물 건설업 | N34: 7210 | O34: 대전지방고용노동청 천안지청 | P34: 건설 | Q34: 28 | R34: 0 | X34: 2024 | Y34: 2024-10-21
A35: 42 | B35: (주)두원전자 | C35: 김종완 | D35: 1298118421 | E35: H0181 | F35: 31428 | G35: 충청남도 아산시 영인면 월선길 4-16 (월선리) | I35: 041-427-0021 | J35: 041-541-2122 | L35: 28119 | M35: 기타 전기 변환장치 제조업 | N35: 7210 | O35: 대전지방고용노동청 천안지청 | P35: 차량용 공조장치 | Q35: 113 | R35: 0 | T35: ldy@dwdec.kr | U35: 이동엽 | V35: 대리 | X35: 2023 | Y35: 2023-06-01
A36: 43 | B36: (주)락앤락 | C36: 이재호 | D36: 31281802120 | E36: H0158 | F36: 17553 | G36: 경기도 안성시 원곡면 만세로 1260 (지문리) | I36: 031-646-3557 | J36: 031-646-3510 | L36: 22299 | M36: 그 외 기타 플라스틱 제품 제조업 | N36: 5170 | O36: 중부지방고용노동청 평택지청 | P36: 가정용 밀폐용기 | Q36: 0 | R36: 0 | T36: wjsgk@locknlock.com | U36: 박성철 | V36: 부장 | X36: 2023 | Y36: 2023-04-20
A37: 44 | B37: (주)락앤락-별지 | E37: H0161 | Q37: 0 | R37: 0 | X37: 2023 | Y37: 2023-04-20
A38: 45 | B38: (주)마노건설 설해수림 신축공사 | C38: 정봉휘 | D38: 2118713085 | E38: H0262 | F38: 25042 | G38: 강원특별자치도 양양군 손양면 공항로 230 (동호리) | L38: 41129 | M38: 기타 비주거용 건물 건설업 | N38: 2130 | O38: 중부지방고용노동청 강릉지청 | P38: 건설 | Q38: 101 | R38: 0 | T38: jhkim1009@kakao.com | U38: 김재훈 | V38: 대리 | W38: 010-8471-8855 | X38: 2024 | Y38: 2024-05-02
A39: 46 | B39: (주)비에스비로지스틱스 | C39: 정관영 | D39: 3098601894 | E39: H0412 | F39: 17023 | G39: 경기도 용인시 처인구 포곡읍 성산로 600 (전대리) | I39: 070-4407-8500 | J39: 031-321-8149 | L39: 46319 | M39: 기타 신선식품 및 단순 가공식품 도매업 | N39: 5110 | O39: 중부지방고용노동청 경기지청 | P39: 물류 서비스 | Q39: 27 | R39: 0 | X39: 2025 | Y39: 2025-10-24
A40: 47 | B40: (주)비에스비푸드 | E40: H0427 | F40: 17553 | G40: 경기도 안성시 원곡면 지문로 203-86 (지문리) | I40: 1588-9109 | J40: 031-618-1238 | L40: 10513 | M40: 곡물 혼합분말 및 반죽 제조업 | N40: 5170 | O40: 중부지방고용노동청 평택지청 | P40: 도우 | Q40: 65 | R40: 0 | T40: ympz1013@gmail.com | U40: 이태구 | V40: 주임 | W40: 010-4034-0430 | X40: 2025 | Y40: 2025-12-23
...

Sheet 사업장현황(25하)
A1: 사 업 장 명 | B1: 대표자 | C1: 관할청 | D1: 주소 | E1: 업종 | F1: 전화번호 | G1: Fax | H1: 담당자 | I1: 직책 | J1: 휴대폰 | K1: 계산서 e-mail | L1: 담당자 e-mail | M1: 사업자번호 | N1: 산재관리번호 | P1: 22하 | Q1: 23상 | R1: 23하 | S1: 24상 | T1: 24하 | U1: 25상 | V1: 25하 | W1: 26상 | X1: 사업장코드 | Y1: 24
A2: (주)마노건설 설해수림 신축공사 | B2: 정봉휘 | C2: 강릉 | D2: 강원특별자치도 양양군 손양면 공항로 230 (동호리) | E2: 건설 | H2: 박현규 | I2: 부장 | J2: 010-3958-0133 | K2: phg102818@daum.net | L2: phg102818@daum.net | M2: 2118713085 | N2: 21187130856 | R2: 신규 | S2: 45414 | T2: 45594 | U2: 45776 | V2: 45961 | W2: t | X2: H0262
A3: 아로마라인 주식회사 | B3: 이동현 | C3: 성남 | D3: 경기도 성남시 중원구 둔촌대로466번길 16 (상대원동) | E3: 제조 | F3: 031-734-7744 | G3: 031-734-7747 | H3: 박가람 | I3: 사원 | J3: 010-2039-1879 | K3: csflim@csfood.com | L3: csflim@csfood.com | M3: 1298147173 | N3: 12981471730 | Q3: 신규 | R3: 45611 | S3: 45447 | T3: 횟수조정 | U3: 45828 | V3: 횟수조정 | W3: t | X3: H0230
A4: 중앙대학교 다빈치캠퍼스 | B4: 박상규 | C4: 평택 | D4: 경기도 안성시 대덕면 서동대로 4726 (내리, 중앙대학교) | E4: 교육 | F4: 031-670-4962 | G4: 031-676-8237 | H4: 유태준 | J4: 010-6556-7900 | K4: tjryu@cau.ac.kr | L4: tjryu@cau.ac.kr | M4: 1088201221 | N4: 10882012210 | Q4: 타기관 신규 | R4: 45625 | S4: 45440 | T4: 45646 | U4: 45800 | V4: 46000 | W4: t | X4: H0232
A5: 건영포장(주) 안성물류센터 | B5: 이건승 | C5: 평택 | D5: 경기도 안성시 양성면 이현배티길 42-12 (이현리) | E5: 제조 | F5: 041-532-5230 | G5: 041-532-3211 | H5: 이재훈 | I5: 사원 | J5: 010-9429-1655 | K5: gy5230@naver.com | L5: gy5230@naver.com | M5: 3128169949 | N5: 31281699490 | Q5: 신규 | R5: 45606 | S5: 45425 | T5: 45631 | U5: 횟수조정 | V5: 45950 | W5: 횟수조정 | X5: H0227
A6: 한경국립대학교 | B6: 이원희 | C6: 평택 | D6: 경기도 안성시 중앙로 327 (석정동, 한경대학교) | E6: 교육 | F6: 031-8046-4122 | H6: 박서완 | I6: 주무관 | J6: 010-5195-7028 | K6: 나라장터 | L6: yuzen007@hknu.ac.kr | M6: 1258300530 | N6: 90700144261 | R6: 타기관 신규 | S6: 45391 | T6: 12/3, 10 | U6: 6/9, 13 | V6: 45959 | W6: t | X6: H0254
A7: (주)엘앤피 | B7: 장은숙 | C7: 평택 | D7: 경기도 평택시 청북읍 백봉길 114-32 (어연리) | E7: 인쇄 | F7: 031-653-1186 | G7: 031-653-1189 | H7: 곽태경 | J7: 010-2538-4319 | K7: jeil112@hanmail.net | L7: uridle78@naver.com | M7: 1198195310 | N7: 11981953100 | Q7: 타기관 신규 | R7: 45554 | S7: 45425 | T7: 45545 | U7: 45736 | V7: 횟수조정 | W7: t | X7: H0215
A8: 제이비엘(JEIL BEST LABEL) | B8: 김영구 | C8: 평택 | D8: 경기도 평택시 청북읍 백봉길 114-32 (어연리) | E8: 인쇄 | F8: 031-653-1186 | G8: 031-653-1189 | H8: 곽태경 | J8: 010-2538-4319 | K8: jeil112@hanmail.net | L8: uridle78@naver.com | M8: 2180124712 | N8: 21801247120 | P8: 타기관 신규 | Q8: 45436 | R8: 45554 | S8: 45425 | T8: 45545 | U8: 45736 | V8: 횟수조정 | W8: t | X8: H0176
A9: (주)삼정오토메이션 | B9: 신동익 | C9: 경기 | D9: 경기도 화성시 동탄산단4길 9-34 (방교동) | E9: 제조 | F9: 031-469-3090 | G9: 031-376-3095 | H9: 백유현 | I9: 대리 | J9: 010-4745-3840 | K9: seohb@sjautomation.com | L9: seohb@sjautomation.com | M9: 1238141133 | N9: 12381411330 | Q9: 신규 | R9: 45548 | S9: 45455 | T9: 45618 | U9: 45798 | V9: 횟수조정 | W9: t | X9: H0214
A10: 주식회사 승일금속 | B10: 유하선 | C10: 경기 | D10: 경기도 화성시 송산면 송산서로239번길 27-35, C동 (지화리) | E10: 제조 | F10: 031-357-3713 | G10: 031-357-3743 | H10: 한희순 | I10: 과장 | J10: 010-8823-4256 | K10: hshan@daeseung.me | L10: hshan@daeseung.me | M10: 4388103502 | N10: 43881035020 | R10: 신규 | S10: 45369 | T10: 45546 | U10: 횟수조정 | V10: 45931 | W10: 횟수조정 | X10: H0244
A11: 오다금속 주식회사 | B11: 최석재 | C11: 경기 | D11: 경기도 화성시 송산면 송산서로239번길 45-33 (지화리) | E11: 제조 | F11: 031-356-4596 | G11: 031-356-4597 | H11: 김청미 | J11: 010-2286-8023 | K11: odm8684@naver.com | L11: odm8684@naver.com | M11: 7328701183 | N11: 73287011830 | R11: 타기관 신규 | S11: 45390 | T11: 45546 | U11: 45726 | V11: 45930 | W11: t | X11: H0253
A12: 경인단조 | B12: 이대연 | C12: 경기 | D12: 경기도 화성시 송산면 송산서로239번길 45-35 (지화리) | E12: 제조 | F12: 031-357-3713 | G12: 031-357-3743 | H12: 한희순 | I12: 과장 | J12: 010-8823-4256 | K12: hshan@daeseung.me | L12: hshan@daeseung.me | M12: 1310866049 | N12: 13108660490 | P12: 타기관 신규 | Q12: 45402 | R12: 45598 | S12: 45369 | T12: 45546 | U12: 45726 | V12: 45930 | W12: t | X12: H0160
A13: 주식회사 대승금속 | B13: 이대연 | C13: 경기 | D13: 경기도 화성시 송산면 송산서로239번길 45-35 (지화리) | E13: 제조 | F13: 031-357-3713 | G13: 031-357-3743 | H13: 한희순 | I13: 과장 | J13: 010-8823-4256 | K13: hshan@daeseung.me | L13: hshan@daeseung.me | M13: 1408166823 | N13: 14081668230 | P13: 타기관 신규 | Q13: 45402 | R13: 45598 | S13: 45369 | T13: 45546 | U13: 45726 | V13: 45930 | W13: t | X13: H0159
A14: (주)신태양 화성공장 | B14: 박용복, 박지종 | C14: 경기 | D14: 경기도 화성시 팔탄면 신양1길 39 (가재리) | E14: 제조 | F14: 031-353-9571 | G14: 031-353-9570 | H14: 이명섭 | I14: 공장장 | J14: 010-8913-6228 | K14: sty2355@daum.net | L14: sty2355@hanmail.net | M14: 1248148819 | N14: 12481488190 | P14: 타기관 신규 | Q14: 45358 | R14: 45542 | S14: 45383 | T14: 45589 | U14: 45744 | V14: 45930 | W14: t | X14: H0127
A15: 주식회사 리한 | B15: 박지훈, 이학선 | C15: 경기 | D15: 경기도 화성시 팔탄면 온천로 16-16 (덕우리) | E15: 제조 | F15: 031-831-2250 | H15: 박종화 | I15: 팀장 | J15: 010-8856-9846 | K15: jonghpark@leehan.com | L15: jonghpark@leehan.com | M15: 1238122214 | N15: 12381222140 | R15: 타기관 신규 | S15: 45457 | T15: 45616 | U15: 45785 | V15: 45965 | W15: t | X15: H0279
A16: 주식회사 와이에이치프라텍 | B16: 김춘규 | C16: 경기 | D16: 경기도 화성시 향남읍 토성로359번길 31 (길성리) | E16: 제조 | F16: 070-8862-7322 | G16: 031-353-7322 | H16: 김춘규 | I16: 대표 | L16: 이주형 지인 사업장 | M16: 1258628830 | N16: 12586288300 | R16: 타기관 신규 | S16: 45422 | T16: 45518 | U16: 45743 | V16: 45931 | W16: 횟수조정 | X16: H0266
A17: 뉴 서울모터스 | B17: 최봉환 | C17: 대전 | D17: 대전광역시 대덕구 갑천도시고속도로 1079 (신대동) | E17: 공업사 | F17: 042-627-4143 | G17: 042-627-4148 | H17: 최봉환 | I17: 대표 | J17: 010-5408-2244 | K17: NS24866@daum.net | L17: NS24866@daum.net | M17: 3030524866 | N17: 30305248660 | P17: 타기관 신규 | Q17: 45387 | R17: 45581 | S17: 45401 | T17: 45540 | U17: 45715 | V17: 45888 | W17: t | X17: H0028
A18: 대청모터스 | B18: 강윤구 | C18: 대전 | D18: 대전광역시 대덕구 대덕대로 1400 (신일동) | E18: 공업사 | F18: 042-931-8935 | G18: 042-931-8936 | H18: 강윤구 | I18: 대표 | J18: 010-9959-8989 | K18: kuk9029@hanmail.net | L18: kuk9029@hanmail.net | M18: 3142044036 | N18: 31420440360 | P18: 타기관 신규 | Q18: 45350 | R18: 45532 | S18: 45349 | T18: 45502 | U18: 45670 | V18: 45859 | W18: t | X18: H0120
A19: 주식회사 신탄특장자동차 | B19: 이창순 | C19: 대전 | D19: 대전광역시 대덕구 대덕대로 1403-1 (문평동) | E19: 공업사 | F19: 042-933-1515 | G19: 042-934-7988 | H19: 조중훈 | I19: 관리부장 | J19: 010-6404-5608 | K19: sttj1001@naver.com | L19: sttj1001@naver.com | M19: 6688601380 | N19: 66886013800 | R19: 타기관 신규 | S19: 45461 | T19: 45582 | U19: 45734 | V19: 45891 | W19: t | X19: H0280
A20: 주식회사 북대전현대상용서비스 | B20: 정진숙 | C20: 대전 | D20: 대전광역시 대덕구 대전로 1324 (읍내동) | E20: 공업사 | F20: 042-634-1122 | G20: 042-631-6705 | H20: 홍준호 | I20: 이사 | J20: 010-9234-8630 | K20: bdj3728@naver.com | L20: bdj3728@naver.com | M20: 3728802425 | N20: 92230124771 | P20: 타기관 신규 | Q20: 45346 | R20: 45534 | S20: 45371 | T20: 45513 | U20: 45699 | V20: 45880 | W20: t | X20: H0045
A21: 태경자동차종합정비 | B21: 윤경수 | C21: 대전 | D21: 대전광역시 대덕구 대전로 1419 (읍내동) | E21: 공업사 | F21: 042-624-0359 | G21: 042-624-0350 | H21: 윤경수 | I21: 대표 | J21: 010-6402-0359 | K21: tk0359@hanmail.net | L21: tk0359@hanmail.net | M21: 3210400394 | N21: 32104003940 | P21: 타기관 신규 | Q21: 45345 | R21: 45513 | S21: 45364 | T21: 45513 | U21: 45699 | V21: 45880 | W21: t | X21: H0044
A22: 명성자동차공업사 | B22: 김기범 외 1명 | C22: 대전 | D22: 대전광역시 대덕구 대전로 1433 (읍내동) | E22: 공업사 | F22: 042-639-2987 | G22: 042-637-2987 | H22: 김기범 | I22: 대표 | J22: 010-3903-2987 | K22: kbkim@hanmail.net | L22: kbkim@hanmail.net | M22: 3052587486 | N22: 30525874860 | P22: 타기관 신규 | Q22: 45360 | R22: 45539 | S22: 45448 | T22: 45541 | U22: 45702 | V22: 45889 | W22: t | X22: H0043
A23: 일급대동자동차공업사 | B23: 지용출 | C23: 대전 | D23: 대전광역시 대덕구 대전로 1431 (읍내동) | E23: 공업사 | F23: 042-935-8181 | G23: 042-935-2345 | H23: 지혁 | I23: 부장 | J23: 010-5423-5389 | K23: yyong1404@hanmail.net | L23: yyong1404@hanmail.net | M23: 3141072983 | N23: 31410729830 | P23: 타기관 신규 | Q23: 45360 | R23: 45539 | S23: 45364 | T23: 45589 | U23: 45702 | V23: 45889 | W23: t | X23: H0042
A24: 한미타올(주) | B24: 여기석 | C24: 대전 | D24: 대전광역시 대덕구 대전로1331번길 50 (읍내동, 한미타올) | E24: 제조 | F24: 042-625-4145 | G24: 042-625-4147 | H24: 조한경 | I24: 상무 | J24: 010-8815-6316 | K24: hanmiacc4141@daum.net | L24: chk8534@hanmail.net | M24: 3068104878 | N24: 30681048780 | R24: 타기관 신규 | S24: 45455 | T24: 45603 | U24: 45785 | V24: 45968 | W24: t | X24: H0274
A25: 세광자동차공업사 | B25: 권형철 | C25: 대전 | D25: 대전광역시 대덕구 대전로1397번안길 54 (읍내동) | E25: 공업사 | F25: 042-623-8252 | G25: 042-623-8251 | H25: 권형철 | I25: 대표 | J25: 010-6432-0782 | K25: 79kwohc@naver.com | L25: 79kwohc@naver.com | M25: 4011261649 | N25: 40112616490 | P25: 타기관 신규 | Q25: 45345 | R25: 45525 | S25: 45345 | T25: 45505 | U25: 45670 | V25: 45859 | W25: t | X25: H0041
A26: 그린자동차공업사 | B26: 이규희 | C26: 대전 | D26: 대전광역시 대덕구 대전로1397번안길 67 (읍내동) | E26: 공업사 | F26: 042-633-7182 | G26: 042-633-7184 | H26: 이규희 | I26: 대표 | J26: 010-5403-1513 | K26: gosi67@naver.com | L26: gosi67@naver.com | M26: 3052115155 | N26: 30521151550 | P26: 신규 | Q26: 45329 | R26: 45513 | S26: 45433 | T26: 45589 | U26: 45702 | V26: 45902 | W26: t | X26: H0105
A27: 삼우자동차정비(자) | B27: 최남식 | C27: 대전 | D27: 대전광역시 대덕구 대화로 101 (대화동) | E27: 공업사 | F27: 042-627-5600 | G27: 042-627-2995 | H27: 최남식 | I27: 대표 | J27: 010-5424-9766 | K27: cns5600@bill36524.com | L27: ksjs1108@nate.com | M27: 3068131720 | N27: 30681317200 | P27: 타기관 신규 | Q27: 45338 | R27: 45521 | S27: 45341 | T27: 45506 | U27: 45673 | V27: 45861 | W27: t | X27: H0112
A28: 대성공업사 | B28: 이기태 외 1명 | C28: 대전 | D28: 대전광역시 대덕구 대화로 16 (대화동) | E28: 공업사 | F28: 042-624-7771 | G28: 042-633-2688 | H28: 이기태 | I28: 대표 | J28: 010-3408-7777 | K28: ds6247771@naver.com | L28: ds6247771@naver.com | M28: 3062971855 | N28: 30629718550 | P28: 타기관 신규 | Q28: 45332 | R28: 45529 | S28: 45342 | T28: 45504 | U28: 45671 | V28: 45860 | W28: t | X28: H0020
A29: 대성모터스 | B29: 박종대 | C29: 대전 | D29: 대전광역시 대덕구 대화로 16 (대화동) | E29: 공업사 | F29: 042-636-0363 | G29: 042-636-0364 | H29: 박종대 | I29: 대표 | J29: 010-5092-0364 | K29: pppt0364@hanmail.net | L29: pppt0364@hanmail.net | M29: 3051899553 | N29: 30518995530 | P29: 타기관 신규 | Q29: 45332 | R29: 45529 | S29: 45342 | T29: 45504 | U29: 45671 | V29: 45860 | W29: t | X29: H0021
